[2024-05-19T03:18:44.935+0000] {local_task_job_runner.py:120} INFO - ::group::Pre task execution logs
[2024-05-19T03:18:44.992+0000] {taskinstance.py:2073} INFO - Dependencies all met for dep_context=non-requeueable deps ti=<TaskInstance: dag_analysis.analysis manual__2024-05-19T03:18:43.360017+00:00 [queued]>
[2024-05-19T03:18:45.003+0000] {taskinstance.py:2073} INFO - Dependencies all met for dep_context=requeueable deps ti=<TaskInstance: dag_analysis.analysis manual__2024-05-19T03:18:43.360017+00:00 [queued]>
[2024-05-19T03:18:45.009+0000] {taskinstance.py:2303} INFO - Starting attempt 1 of 6
[2024-05-19T03:18:45.049+0000] {taskinstance.py:2327} INFO - Executing <Task(PythonOperator): analysis> on 2024-05-19 03:18:43.360017+00:00
[2024-05-19T03:18:45.068+0000] {logging_mixin.py:188} WARNING - /home/***/.local/lib/python3.12/site-packages/***/task/task_runner/standard_task_runner.py:61 DeprecationWarning: This process (pid=177) is multi-threaded, use of fork() may lead to deadlocks in the child.
[2024-05-19T03:18:45.067+0000] {standard_task_runner.py:90} INFO - Running: ['***', 'tasks', 'run', 'dag_analysis', 'analysis', 'manual__2024-05-19T03:18:43.360017+00:00', '--job-id', '559', '--raw', '--subdir', 'DAGS_FOLDER/dag1.py', '--cfg-path', '/tmp/tmpwa1cif4h']
[2024-05-19T03:18:45.078+0000] {standard_task_runner.py:63} INFO - Started process 196 to run task
[2024-05-19T03:18:45.078+0000] {standard_task_runner.py:91} INFO - Job 559: Subtask analysis
[2024-05-19T03:18:45.210+0000] {task_command.py:426} INFO - Running <TaskInstance: dag_analysis.analysis manual__2024-05-19T03:18:43.360017+00:00 [running]> on host cf8d95dc7aa1
[2024-05-19T03:18:45.434+0000] {taskinstance.py:2644} INFO - Exporting env vars: AIRFLOW_CTX_DAG_OWNER='bses' AIRFLOW_CTX_DAG_ID='dag_analysis' AIRFLOW_CTX_TASK_ID='analysis' AIRFLOW_CTX_EXECUTION_DATE='2024-05-19T03:18:43.360017+00:00' AIRFLOW_CTX_TRY_NUMBER='1' AIRFLOW_CTX_DAG_RUN_ID='manual__2024-05-19T03:18:43.360017+00:00'
[2024-05-19T03:18:45.437+0000] {taskinstance.py:430} INFO - ::endgroup::
[2024-05-19T03:18:45.538+0000] {taskinstance.py:441} INFO - ::group::Post task execution logs
[2024-05-19T03:18:45.543+0000] {taskinstance.py:2890} ERROR - Task failed with exception
Traceback (most recent call last):
  File "/home/airflow/.local/lib/python3.12/site-packages/mysql/connector/connection_cext.py", line 323, in _open_connection
    self._cmysql.connect(**cnx_kwargs)
_mysql_connector.MySQLInterfaceError: Can't connect to MySQL server on 'Bisheshs-MacBook-Pro.local:3306' (22)

The above exception was the direct cause of the following exception:

Traceback (most recent call last):
  File "/home/airflow/.local/lib/python3.12/site-packages/airflow/models/taskinstance.py", line 465, in _execute_task
    result = _execute_callable(context=context, **execute_callable_kwargs)
             ^^^^^^^^^^^^^^^^^^^^^^^^^^^^^^^^^^^^^^^^^^^^^^^^^^^^^^^^^^^^^
  File "/home/airflow/.local/lib/python3.12/site-packages/airflow/models/taskinstance.py", line 432, in _execute_callable
    return execute_callable(context=context, **execute_callable_kwargs)
           ^^^^^^^^^^^^^^^^^^^^^^^^^^^^^^^^^^^^^^^^^^^^^^^^^^^^^^^^^^^^
  File "/home/airflow/.local/lib/python3.12/site-packages/airflow/models/baseoperator.py", line 400, in wrapper
    return func(self, *args, **kwargs)
           ^^^^^^^^^^^^^^^^^^^^^^^^^^^
  File "/home/airflow/.local/lib/python3.12/site-packages/airflow/operators/python.py", line 235, in execute
    return_value = self.execute_callable()
                   ^^^^^^^^^^^^^^^^^^^^^^^
  File "/home/airflow/.local/lib/python3.12/site-packages/airflow/operators/python.py", line 252, in execute_callable
    return self.python_callable(*self.op_args, **self.op_kwargs)
           ^^^^^^^^^^^^^^^^^^^^^^^^^^^^^^^^^^^^^^^^^^^^^^^^^^^^^
  File "/opt/airflow/dags/dag1.py", line 8, in run
    conn = connection.connect(
           ^^^^^^^^^^^^^^^^^^^
  File "/home/airflow/.local/lib/python3.12/site-packages/mysql/connector/pooling.py", line 322, in connect
    return CMySQLConnection(*args, **kwargs)
           ^^^^^^^^^^^^^^^^^^^^^^^^^^^^^^^^^
  File "/home/airflow/.local/lib/python3.12/site-packages/mysql/connector/connection_cext.py", line 140, in __init__
    self.connect(**kwargs)
  File "/home/airflow/.local/lib/python3.12/site-packages/mysql/connector/abstracts.py", line 1363, in connect
    self._open_connection()
  File "/home/airflow/.local/lib/python3.12/site-packages/mysql/connector/connection_cext.py", line 328, in _open_connection
    raise get_mysql_exception(
mysql.connector.errors.DatabaseError: 2003 (HY000): Can't connect to MySQL server on 'Bisheshs-MacBook-Pro.local:3306' (22)
[2024-05-19T03:18:45.570+0000] {taskinstance.py:1205} INFO - Marking task as UP_FOR_RETRY. dag_id=dag_analysis, task_id=analysis, execution_date=20240519T031843, start_date=20240519T031844, end_date=20240519T031845
[2024-05-19T03:18:45.688+0000] {standard_task_runner.py:110} ERROR - Failed to execute job 559 for task analysis (2003 (HY000): Can't connect to MySQL server on 'Bisheshs-MacBook-Pro.local:3306' (22); 196)
[2024-05-19T03:18:45.713+0000] {local_task_job_runner.py:240} INFO - Task exited with return code 1
[2024-05-19T03:18:45.794+0000] {taskinstance.py:3482} INFO - 0 downstream tasks scheduled from follow-on schedule check
[2024-05-19T03:18:45.811+0000] {local_task_job_runner.py:222} INFO - ::endgroup::
