[2024-05-16T11:22:33.302+0000] {local_task_job_runner.py:120} INFO - ::group::Pre task execution logs
[2024-05-16T11:22:33.334+0000] {taskinstance.py:2073} INFO - Dependencies all met for dep_context=non-requeueable deps ti=<TaskInstance: dag_tables.import_table4 manual__2024-05-16T11:22:29.083466+00:00 [queued]>
[2024-05-16T11:22:33.341+0000] {taskinstance.py:2073} INFO - Dependencies all met for dep_context=requeueable deps ti=<TaskInstance: dag_tables.import_table4 manual__2024-05-16T11:22:29.083466+00:00 [queued]>
[2024-05-16T11:22:33.343+0000] {taskinstance.py:2303} INFO - Starting attempt 1 of 6
[2024-05-16T11:22:33.352+0000] {taskinstance.py:2327} INFO - Executing <Task(BashOperator): import_table4> on 2024-05-16 11:22:29.083466+00:00
[2024-05-16T11:22:33.358+0000] {logging_mixin.py:188} WARNING - /home/***/.local/lib/python3.12/site-packages/***/task/task_runner/standard_task_runner.py:61 DeprecationWarning: This process (pid=582) is multi-threaded, use of fork() may lead to deadlocks in the child.
[2024-05-16T11:22:33.366+0000] {standard_task_runner.py:63} INFO - Started process 591 to run task
[2024-05-16T11:22:33.364+0000] {standard_task_runner.py:90} INFO - Running: ['***', 'tasks', 'run', 'dag_tables', 'import_table4', 'manual__2024-05-16T11:22:29.083466+00:00', '--job-id', '469', '--raw', '--subdir', 'DAGS_FOLDER/dag_mysql.py', '--cfg-path', '/tmp/tmpiq5w0igl']
[2024-05-16T11:22:33.374+0000] {standard_task_runner.py:91} INFO - Job 469: Subtask import_table4
[2024-05-16T11:22:33.419+0000] {task_command.py:426} INFO - Running <TaskInstance: dag_tables.import_table4 manual__2024-05-16T11:22:29.083466+00:00 [running]> on host 7084a6d88d3b
[2024-05-16T11:22:33.477+0000] {taskinstance.py:2644} INFO - Exporting env vars: AIRFLOW_CTX_DAG_OWNER='bses' AIRFLOW_CTX_DAG_ID='dag_tables' AIRFLOW_CTX_TASK_ID='import_table4' AIRFLOW_CTX_EXECUTION_DATE='2024-05-16T11:22:29.083466+00:00' AIRFLOW_CTX_TRY_NUMBER='1' AIRFLOW_CTX_DAG_RUN_ID='manual__2024-05-16T11:22:29.083466+00:00'
[2024-05-16T11:22:33.478+0000] {taskinstance.py:430} INFO - ::endgroup::
[2024-05-16T11:22:33.484+0000] {subprocess.py:63} INFO - Tmp dir root location: /tmp
[2024-05-16T11:22:33.484+0000] {subprocess.py:75} INFO - Running command: ['/usr/bin/bash', '-c', '\n                mysql -h host.docker.internal -u root --password=12345678 test < /opt/***/dags/report_table.sql\n                ']
[2024-05-16T11:22:33.489+0000] {subprocess.py:86} INFO - Output:
[2024-05-16T11:22:33.519+0000] {subprocess.py:93} INFO - ERROR 1050 (42S01) at line 8: Table 'customer_profile' already exists
[2024-05-16T11:22:33.520+0000] {subprocess.py:97} INFO - Command exited with return code 1
[2024-05-16T11:22:33.522+0000] {taskinstance.py:441} INFO - ::group::Post task execution logs
[2024-05-16T11:22:33.530+0000] {taskinstance.py:2890} ERROR - Task failed with exception
Traceback (most recent call last):
  File "/home/airflow/.local/lib/python3.12/site-packages/airflow/models/taskinstance.py", line 465, in _execute_task
    result = _execute_callable(context=context, **execute_callable_kwargs)
             ^^^^^^^^^^^^^^^^^^^^^^^^^^^^^^^^^^^^^^^^^^^^^^^^^^^^^^^^^^^^^
  File "/home/airflow/.local/lib/python3.12/site-packages/airflow/models/taskinstance.py", line 432, in _execute_callable
    return execute_callable(context=context, **execute_callable_kwargs)
           ^^^^^^^^^^^^^^^^^^^^^^^^^^^^^^^^^^^^^^^^^^^^^^^^^^^^^^^^^^^^
  File "/home/airflow/.local/lib/python3.12/site-packages/airflow/models/baseoperator.py", line 400, in wrapper
    return func(self, *args, **kwargs)
           ^^^^^^^^^^^^^^^^^^^^^^^^^^^
  File "/home/airflow/.local/lib/python3.12/site-packages/airflow/operators/bash.py", line 243, in execute
    raise AirflowException(
airflow.exceptions.AirflowException: Bash command failed. The command returned a non-zero exit code 1.
[2024-05-16T11:22:33.534+0000] {taskinstance.py:1205} INFO - Marking task as UP_FOR_RETRY. dag_id=dag_tables, task_id=import_table4, execution_date=20240516T112229, start_date=20240516T112233, end_date=20240516T112233
[2024-05-16T11:22:33.545+0000] {standard_task_runner.py:110} ERROR - Failed to execute job 469 for task import_table4 (Bash command failed. The command returned a non-zero exit code 1.; 591)
[2024-05-16T11:22:33.560+0000] {local_task_job_runner.py:240} INFO - Task exited with return code 1
[2024-05-16T11:22:33.572+0000] {taskinstance.py:3482} INFO - 0 downstream tasks scheduled from follow-on schedule check
[2024-05-16T11:22:33.574+0000] {local_task_job_runner.py:222} INFO - ::endgroup::
