[2024-05-16T11:19:47.911+0000] {local_task_job_runner.py:120} INFO - ::group::Pre task execution logs
[2024-05-16T11:19:47.951+0000] {taskinstance.py:2073} INFO - Dependencies all met for dep_context=non-requeueable deps ti=<TaskInstance: dag_tables.import_table1 manual__2024-05-16T11:19:46.837980+00:00 [queued]>
[2024-05-16T11:19:47.957+0000] {taskinstance.py:2073} INFO - Dependencies all met for dep_context=requeueable deps ti=<TaskInstance: dag_tables.import_table1 manual__2024-05-16T11:19:46.837980+00:00 [queued]>
[2024-05-16T11:19:47.957+0000] {taskinstance.py:2303} INFO - Starting attempt 1 of 6
[2024-05-16T11:19:47.974+0000] {taskinstance.py:2327} INFO - Executing <Task(BashOperator): import_table1> on 2024-05-16 11:19:46.837980+00:00
[2024-05-16T11:19:47.982+0000] {standard_task_runner.py:90} INFO - Running: ['***', 'tasks', 'run', 'dag_tables', 'import_table1', 'manual__2024-05-16T11:19:46.837980+00:00', '--job-id', '380', '--raw', '--subdir', 'DAGS_FOLDER/dag_mysql.py', '--cfg-path', '/tmp/tmp06n1_zvq']
[2024-05-16T11:19:47.987+0000] {standard_task_runner.py:91} INFO - Job 380: Subtask import_table1
[2024-05-16T11:19:47.985+0000] {logging_mixin.py:188} WARNING - /home/***/.local/lib/python3.12/site-packages/***/task/task_runner/standard_task_runner.py:61 DeprecationWarning: This process (pid=186) is multi-threaded, use of fork() may lead to deadlocks in the child.
[2024-05-16T11:19:47.989+0000] {standard_task_runner.py:63} INFO - Started process 191 to run task
[2024-05-16T11:19:48.035+0000] {task_command.py:426} INFO - Running <TaskInstance: dag_tables.import_table1 manual__2024-05-16T11:19:46.837980+00:00 [running]> on host 7084a6d88d3b
[2024-05-16T11:19:48.102+0000] {taskinstance.py:2644} INFO - Exporting env vars: AIRFLOW_CTX_DAG_OWNER='bses' AIRFLOW_CTX_DAG_ID='dag_tables' AIRFLOW_CTX_TASK_ID='import_table1' AIRFLOW_CTX_EXECUTION_DATE='2024-05-16T11:19:46.837980+00:00' AIRFLOW_CTX_TRY_NUMBER='1' AIRFLOW_CTX_DAG_RUN_ID='manual__2024-05-16T11:19:46.837980+00:00'
[2024-05-16T11:19:48.104+0000] {taskinstance.py:430} INFO - ::endgroup::
[2024-05-16T11:19:48.121+0000] {subprocess.py:63} INFO - Tmp dir root location: /tmp
[2024-05-16T11:19:48.122+0000] {subprocess.py:75} INFO - Running command: ['/usr/bin/bash', '-c', '\n            mysql -h host.docker.internal -u root --password=12345678 test < /opt/***/dags/products.sql;\n           ']
[2024-05-16T11:19:48.133+0000] {subprocess.py:86} INFO - Output:
[2024-05-16T11:19:48.246+0000] {subprocess.py:93} INFO - ERROR 1146 (42S02) at line 38: Table 'test.products' doesn't exist
[2024-05-16T11:19:48.249+0000] {subprocess.py:97} INFO - Command exited with return code 1
[2024-05-16T11:19:48.251+0000] {taskinstance.py:441} INFO - ::group::Post task execution logs
[2024-05-16T11:19:48.265+0000] {taskinstance.py:2890} ERROR - Task failed with exception
Traceback (most recent call last):
  File "/home/airflow/.local/lib/python3.12/site-packages/airflow/models/taskinstance.py", line 465, in _execute_task
    result = _execute_callable(context=context, **execute_callable_kwargs)
             ^^^^^^^^^^^^^^^^^^^^^^^^^^^^^^^^^^^^^^^^^^^^^^^^^^^^^^^^^^^^^
  File "/home/airflow/.local/lib/python3.12/site-packages/airflow/models/taskinstance.py", line 432, in _execute_callable
    return execute_callable(context=context, **execute_callable_kwargs)
           ^^^^^^^^^^^^^^^^^^^^^^^^^^^^^^^^^^^^^^^^^^^^^^^^^^^^^^^^^^^^
  File "/home/airflow/.local/lib/python3.12/site-packages/airflow/models/baseoperator.py", line 400, in wrapper
    return func(self, *args, **kwargs)
           ^^^^^^^^^^^^^^^^^^^^^^^^^^^
  File "/home/airflow/.local/lib/python3.12/site-packages/airflow/operators/bash.py", line 243, in execute
    raise AirflowException(
airflow.exceptions.AirflowException: Bash command failed. The command returned a non-zero exit code 1.
[2024-05-16T11:19:48.273+0000] {taskinstance.py:1205} INFO - Marking task as UP_FOR_RETRY. dag_id=dag_tables, task_id=import_table1, execution_date=20240516T111946, start_date=20240516T111947, end_date=20240516T111948
[2024-05-16T11:19:48.321+0000] {standard_task_runner.py:110} ERROR - Failed to execute job 380 for task import_table1 (Bash command failed. The command returned a non-zero exit code 1.; 191)
[2024-05-16T11:19:48.339+0000] {local_task_job_runner.py:240} INFO - Task exited with return code 1
[2024-05-16T11:19:48.421+0000] {taskinstance.py:3482} INFO - 0 downstream tasks scheduled from follow-on schedule check
[2024-05-16T11:19:48.425+0000] {local_task_job_runner.py:222} INFO - ::endgroup::
