[2024-05-15T10:15:44.220+0000] {local_task_job_runner.py:120} INFO - ::group::Pre task execution logs
[2024-05-15T10:15:44.271+0000] {taskinstance.py:2073} INFO - Dependencies all met for dep_context=non-requeueable deps ti=<TaskInstance: dag_hdfs.save scheduled__2024-05-13T00:00:00+00:00 [queued]>
[2024-05-15T10:15:44.280+0000] {taskinstance.py:2073} INFO - Dependencies all met for dep_context=requeueable deps ti=<TaskInstance: dag_hdfs.save scheduled__2024-05-13T00:00:00+00:00 [queued]>
[2024-05-15T10:15:44.285+0000] {taskinstance.py:2303} INFO - Starting attempt 1 of 6
[2024-05-15T10:15:44.297+0000] {taskinstance.py:2327} INFO - Executing <Task(PythonOperator): save> on 2024-05-13 00:00:00+00:00
[2024-05-15T10:15:44.312+0000] {standard_task_runner.py:90} INFO - Running: ['***', 'tasks', 'run', 'dag_hdfs', 'save', 'scheduled__2024-05-13T00:00:00+00:00', '--job-id', '157', '--raw', '--subdir', 'DAGS_FOLDER/hdfs_dag.py', '--cfg-path', '/tmp/tmpnosqo8rg']
[2024-05-15T10:15:44.315+0000] {logging_mixin.py:188} WARNING - /home/***/.local/lib/python3.12/site-packages/***/task/task_runner/standard_task_runner.py:61 DeprecationWarning: This process (pid=259) is multi-threaded, use of fork() may lead to deadlocks in the child.
[2024-05-15T10:15:44.316+0000] {standard_task_runner.py:63} INFO - Started process 291 to run task
[2024-05-15T10:15:44.315+0000] {standard_task_runner.py:91} INFO - Job 157: Subtask save
[2024-05-15T10:15:44.375+0000] {task_command.py:426} INFO - Running <TaskInstance: dag_hdfs.save scheduled__2024-05-13T00:00:00+00:00 [running]> on host f85b7a0b58b5
[2024-05-15T10:15:44.445+0000] {taskinstance.py:2644} INFO - Exporting env vars: AIRFLOW_CTX_DAG_OWNER='bses' AIRFLOW_CTX_DAG_ID='dag_hdfs' AIRFLOW_CTX_TASK_ID='save' AIRFLOW_CTX_EXECUTION_DATE='2024-05-13T00:00:00+00:00' AIRFLOW_CTX_TRY_NUMBER='1' AIRFLOW_CTX_DAG_RUN_ID='scheduled__2024-05-13T00:00:00+00:00'
[2024-05-15T10:15:44.448+0000] {taskinstance.py:430} INFO - ::endgroup::
[2024-05-15T10:15:44.457+0000] {logging_mixin.py:188} INFO - Error  /bin/sh: 1: hdfs: Permission denied
[2024-05-15T10:15:44.459+0000] {python.py:237} INFO - Done. Returned value was: None
[2024-05-15T10:15:44.460+0000] {taskinstance.py:441} INFO - ::group::Post task execution logs
[2024-05-15T10:15:44.473+0000] {taskinstance.py:1205} INFO - Marking task as SUCCESS. dag_id=dag_hdfs, task_id=save, execution_date=20240513T000000, start_date=20240515T101544, end_date=20240515T101544
[2024-05-15T10:15:44.502+0000] {local_task_job_runner.py:240} INFO - Task exited with return code 0
[2024-05-15T10:15:44.526+0000] {taskinstance.py:3482} INFO - 1 downstream tasks scheduled from follow-on schedule check
[2024-05-15T10:15:44.528+0000] {local_task_job_runner.py:222} INFO - ::endgroup::
[2024-05-15T10:20:36.432+0000] {local_task_job_runner.py:120} INFO - ::group::Pre task execution logs
[2024-05-15T10:20:36.450+0000] {taskinstance.py:2073} INFO - Dependencies all met for dep_context=non-requeueable deps ti=<TaskInstance: dag_hdfs.save scheduled__2024-05-13T00:00:00+00:00 [queued]>
[2024-05-15T10:20:36.456+0000] {taskinstance.py:2073} INFO - Dependencies all met for dep_context=requeueable deps ti=<TaskInstance: dag_hdfs.save scheduled__2024-05-13T00:00:00+00:00 [queued]>
[2024-05-15T10:20:36.456+0000] {taskinstance.py:2303} INFO - Starting attempt 1 of 6
[2024-05-15T10:20:36.465+0000] {taskinstance.py:2327} INFO - Executing <Task(BashOperator): save> on 2024-05-13 00:00:00+00:00
[2024-05-15T10:20:36.470+0000] {logging_mixin.py:188} WARNING - /home/***/.local/lib/python3.12/site-packages/***/task/task_runner/standard_task_runner.py:61 DeprecationWarning: This process (pid=525) is multi-threaded, use of fork() may lead to deadlocks in the child.
[2024-05-15T10:20:36.471+0000] {standard_task_runner.py:63} INFO - Started process 546 to run task
[2024-05-15T10:20:36.470+0000] {standard_task_runner.py:90} INFO - Running: ['***', 'tasks', 'run', 'dag_hdfs', 'save', 'scheduled__2024-05-13T00:00:00+00:00', '--job-id', '182', '--raw', '--subdir', 'DAGS_FOLDER/hdfs_dag.py', '--cfg-path', '/tmp/tmp4emu6f1p']
[2024-05-15T10:20:36.472+0000] {standard_task_runner.py:91} INFO - Job 182: Subtask save
[2024-05-15T10:20:36.503+0000] {task_command.py:426} INFO - Running <TaskInstance: dag_hdfs.save scheduled__2024-05-13T00:00:00+00:00 [running]> on host f85b7a0b58b5
[2024-05-15T10:20:36.547+0000] {taskinstance.py:2644} INFO - Exporting env vars: AIRFLOW_CTX_DAG_OWNER='bses' AIRFLOW_CTX_DAG_ID='dag_hdfs' AIRFLOW_CTX_TASK_ID='save' AIRFLOW_CTX_EXECUTION_DATE='2024-05-13T00:00:00+00:00' AIRFLOW_CTX_TRY_NUMBER='1' AIRFLOW_CTX_DAG_RUN_ID='scheduled__2024-05-13T00:00:00+00:00'
[2024-05-15T10:20:36.548+0000] {taskinstance.py:430} INFO - ::endgroup::
[2024-05-15T10:20:36.554+0000] {subprocess.py:63} INFO - Tmp dir root location: /tmp
[2024-05-15T10:20:36.555+0000] {subprocess.py:75} INFO - Running command: ['/usr/bin/bash', '-c', 'hdfs dfs -mkdir /tmp']
[2024-05-15T10:20:36.560+0000] {subprocess.py:86} INFO - Output:
[2024-05-15T10:20:36.561+0000] {subprocess.py:93} INFO - /usr/bin/bash: line 1: hdfs: command not found
[2024-05-15T10:20:36.561+0000] {subprocess.py:97} INFO - Command exited with return code 127
[2024-05-15T10:20:36.562+0000] {taskinstance.py:441} INFO - ::group::Post task execution logs
[2024-05-15T10:20:36.567+0000] {taskinstance.py:2890} ERROR - Task failed with exception
Traceback (most recent call last):
  File "/home/airflow/.local/lib/python3.12/site-packages/airflow/models/taskinstance.py", line 465, in _execute_task
    result = _execute_callable(context=context, **execute_callable_kwargs)
             ^^^^^^^^^^^^^^^^^^^^^^^^^^^^^^^^^^^^^^^^^^^^^^^^^^^^^^^^^^^^^
  File "/home/airflow/.local/lib/python3.12/site-packages/airflow/models/taskinstance.py", line 432, in _execute_callable
    return execute_callable(context=context, **execute_callable_kwargs)
           ^^^^^^^^^^^^^^^^^^^^^^^^^^^^^^^^^^^^^^^^^^^^^^^^^^^^^^^^^^^^
  File "/home/airflow/.local/lib/python3.12/site-packages/airflow/models/baseoperator.py", line 400, in wrapper
    return func(self, *args, **kwargs)
           ^^^^^^^^^^^^^^^^^^^^^^^^^^^
  File "/home/airflow/.local/lib/python3.12/site-packages/airflow/operators/bash.py", line 243, in execute
    raise AirflowException(
airflow.exceptions.AirflowException: Bash command failed. The command returned a non-zero exit code 127.
[2024-05-15T10:20:36.570+0000] {taskinstance.py:1205} INFO - Marking task as UP_FOR_RETRY. dag_id=dag_hdfs, task_id=save, execution_date=20240513T000000, start_date=20240515T102036, end_date=20240515T102036
[2024-05-15T10:20:36.576+0000] {standard_task_runner.py:110} ERROR - Failed to execute job 182 for task save (Bash command failed. The command returned a non-zero exit code 127.; 546)
[2024-05-15T10:20:36.610+0000] {local_task_job_runner.py:240} INFO - Task exited with return code 1
[2024-05-15T10:20:36.618+0000] {taskinstance.py:3482} INFO - 0 downstream tasks scheduled from follow-on schedule check
[2024-05-15T10:20:36.619+0000] {local_task_job_runner.py:222} INFO - ::endgroup::
[2024-05-15T10:31:15.714+0000] {local_task_job_runner.py:120} INFO - ::group::Pre task execution logs
[2024-05-15T10:31:15.746+0000] {taskinstance.py:2073} INFO - Dependencies all met for dep_context=non-requeueable deps ti=<TaskInstance: dag_hdfs.save scheduled__2024-05-13T00:00:00+00:00 [queued]>
[2024-05-15T10:31:15.756+0000] {taskinstance.py:2073} INFO - Dependencies all met for dep_context=requeueable deps ti=<TaskInstance: dag_hdfs.save scheduled__2024-05-13T00:00:00+00:00 [queued]>
[2024-05-15T10:31:15.760+0000] {taskinstance.py:2303} INFO - Starting attempt 1 of 6
[2024-05-15T10:31:15.889+0000] {taskinstance.py:2327} INFO - Executing <Task(BashOperator): save> on 2024-05-13 00:00:00+00:00
[2024-05-15T10:31:15.896+0000] {standard_task_runner.py:90} INFO - Running: ['***', 'tasks', 'run', 'dag_hdfs', 'save', 'scheduled__2024-05-13T00:00:00+00:00', '--job-id', '212', '--raw', '--subdir', 'DAGS_FOLDER/hdfs_dag.py', '--cfg-path', '/tmp/tmpqgvl72h1']
[2024-05-15T10:31:15.897+0000] {logging_mixin.py:188} WARNING - /home/***/.local/lib/python3.12/site-packages/***/task/task_runner/standard_task_runner.py:61 DeprecationWarning: This process (pid=222) is multi-threaded, use of fork() may lead to deadlocks in the child.
[2024-05-15T10:31:15.898+0000] {standard_task_runner.py:91} INFO - Job 212: Subtask save
[2024-05-15T10:31:15.898+0000] {standard_task_runner.py:63} INFO - Started process 247 to run task
[2024-05-15T10:31:15.928+0000] {task_command.py:426} INFO - Running <TaskInstance: dag_hdfs.save scheduled__2024-05-13T00:00:00+00:00 [running]> on host 8fa157e7798a
[2024-05-15T10:31:15.968+0000] {taskinstance.py:2644} INFO - Exporting env vars: AIRFLOW_CTX_DAG_OWNER='bses' AIRFLOW_CTX_DAG_ID='dag_hdfs' AIRFLOW_CTX_TASK_ID='save' AIRFLOW_CTX_EXECUTION_DATE='2024-05-13T00:00:00+00:00' AIRFLOW_CTX_TRY_NUMBER='1' AIRFLOW_CTX_DAG_RUN_ID='scheduled__2024-05-13T00:00:00+00:00'
[2024-05-15T10:31:15.969+0000] {taskinstance.py:430} INFO - ::endgroup::
[2024-05-15T10:31:15.976+0000] {subprocess.py:63} INFO - Tmp dir root location: /tmp
[2024-05-15T10:31:15.978+0000] {subprocess.py:75} INFO - Running command: ['/usr/bin/bash', '-c', 'hdfs dfs -mkdir /tmp']
[2024-05-15T10:31:15.983+0000] {subprocess.py:86} INFO - Output:
[2024-05-15T10:31:15.984+0000] {subprocess.py:93} INFO - /usr/bin/bash: line 1: hdfs: command not found
[2024-05-15T10:31:15.985+0000] {subprocess.py:97} INFO - Command exited with return code 127
[2024-05-15T10:31:15.985+0000] {taskinstance.py:441} INFO - ::group::Post task execution logs
[2024-05-15T10:31:15.990+0000] {taskinstance.py:2890} ERROR - Task failed with exception
Traceback (most recent call last):
  File "/home/airflow/.local/lib/python3.12/site-packages/airflow/models/taskinstance.py", line 465, in _execute_task
    result = _execute_callable(context=context, **execute_callable_kwargs)
             ^^^^^^^^^^^^^^^^^^^^^^^^^^^^^^^^^^^^^^^^^^^^^^^^^^^^^^^^^^^^^
  File "/home/airflow/.local/lib/python3.12/site-packages/airflow/models/taskinstance.py", line 432, in _execute_callable
    return execute_callable(context=context, **execute_callable_kwargs)
           ^^^^^^^^^^^^^^^^^^^^^^^^^^^^^^^^^^^^^^^^^^^^^^^^^^^^^^^^^^^^
  File "/home/airflow/.local/lib/python3.12/site-packages/airflow/models/baseoperator.py", line 400, in wrapper
    return func(self, *args, **kwargs)
           ^^^^^^^^^^^^^^^^^^^^^^^^^^^
  File "/home/airflow/.local/lib/python3.12/site-packages/airflow/operators/bash.py", line 243, in execute
    raise AirflowException(
airflow.exceptions.AirflowException: Bash command failed. The command returned a non-zero exit code 127.
[2024-05-15T10:31:15.993+0000] {taskinstance.py:1205} INFO - Marking task as UP_FOR_RETRY. dag_id=dag_hdfs, task_id=save, execution_date=20240513T000000, start_date=20240515T103115, end_date=20240515T103115
[2024-05-15T10:31:16.001+0000] {standard_task_runner.py:110} ERROR - Failed to execute job 212 for task save (Bash command failed. The command returned a non-zero exit code 127.; 247)
[2024-05-15T10:31:16.039+0000] {local_task_job_runner.py:240} INFO - Task exited with return code 1
[2024-05-15T10:31:16.049+0000] {taskinstance.py:3482} INFO - 0 downstream tasks scheduled from follow-on schedule check
[2024-05-15T10:31:16.052+0000] {local_task_job_runner.py:222} INFO - ::endgroup::
