[2024-05-16T11:19:50.653+0000] {local_task_job_runner.py:120} INFO - ::group::Pre task execution logs
[2024-05-16T11:19:50.684+0000] {taskinstance.py:2073} INFO - Dependencies all met for dep_context=non-requeueable deps ti=<TaskInstance: dag_tables.import_table3 scheduled__2024-05-14T00:00:00+00:00 [queued]>
[2024-05-16T11:19:50.692+0000] {taskinstance.py:2073} INFO - Dependencies all met for dep_context=requeueable deps ti=<TaskInstance: dag_tables.import_table3 scheduled__2024-05-14T00:00:00+00:00 [queued]>
[2024-05-16T11:19:50.697+0000] {taskinstance.py:2303} INFO - Starting attempt 1 of 6
[2024-05-16T11:19:50.710+0000] {taskinstance.py:2327} INFO - Executing <Task(BashOperator): import_table3> on 2024-05-14 00:00:00+00:00
[2024-05-16T11:19:50.716+0000] {logging_mixin.py:188} WARNING - /home/***/.local/lib/python3.12/site-packages/***/task/task_runner/standard_task_runner.py:61 DeprecationWarning: This process (pid=329) is multi-threaded, use of fork() may lead to deadlocks in the child.
[2024-05-16T11:19:50.719+0000] {standard_task_runner.py:63} INFO - Started process 344 to run task
[2024-05-16T11:19:50.717+0000] {standard_task_runner.py:90} INFO - Running: ['***', 'tasks', 'run', 'dag_tables', 'import_table3', 'scheduled__2024-05-14T00:00:00+00:00', '--job-id', '421', '--raw', '--subdir', 'DAGS_FOLDER/dag_mysql.py', '--cfg-path', '/tmp/tmp2ed1bwub']
[2024-05-16T11:19:50.722+0000] {standard_task_runner.py:91} INFO - Job 421: Subtask import_table3
[2024-05-16T11:19:50.776+0000] {task_command.py:426} INFO - Running <TaskInstance: dag_tables.import_table3 scheduled__2024-05-14T00:00:00+00:00 [running]> on host 7084a6d88d3b
[2024-05-16T11:19:50.864+0000] {taskinstance.py:2644} INFO - Exporting env vars: AIRFLOW_CTX_DAG_OWNER='bses' AIRFLOW_CTX_DAG_ID='dag_tables' AIRFLOW_CTX_TASK_ID='import_table3' AIRFLOW_CTX_EXECUTION_DATE='2024-05-14T00:00:00+00:00' AIRFLOW_CTX_TRY_NUMBER='1' AIRFLOW_CTX_DAG_RUN_ID='scheduled__2024-05-14T00:00:00+00:00'
[2024-05-16T11:19:50.867+0000] {taskinstance.py:430} INFO - ::endgroup::
[2024-05-16T11:19:50.879+0000] {subprocess.py:63} INFO - Tmp dir root location: /tmp
[2024-05-16T11:19:50.882+0000] {subprocess.py:75} INFO - Running command: ['/usr/bin/bash', '-c', '\n                mysql -h host.docker.internal -u root --password=12345678 test < /opt/***/dags/product_category_map.sql;\n                ']
[2024-05-16T11:19:50.894+0000] {subprocess.py:86} INFO - Output:
[2024-05-16T11:19:50.957+0000] {subprocess.py:93} INFO - ERROR 1050 (42S01) at line 25: Table 'product_category_map' already exists
[2024-05-16T11:19:50.960+0000] {subprocess.py:97} INFO - Command exited with return code 1
[2024-05-16T11:19:50.972+0000] {taskinstance.py:441} INFO - ::group::Post task execution logs
[2024-05-16T11:19:50.989+0000] {taskinstance.py:2890} ERROR - Task failed with exception
Traceback (most recent call last):
  File "/home/airflow/.local/lib/python3.12/site-packages/airflow/models/taskinstance.py", line 465, in _execute_task
    result = _execute_callable(context=context, **execute_callable_kwargs)
             ^^^^^^^^^^^^^^^^^^^^^^^^^^^^^^^^^^^^^^^^^^^^^^^^^^^^^^^^^^^^^
  File "/home/airflow/.local/lib/python3.12/site-packages/airflow/models/taskinstance.py", line 432, in _execute_callable
    return execute_callable(context=context, **execute_callable_kwargs)
           ^^^^^^^^^^^^^^^^^^^^^^^^^^^^^^^^^^^^^^^^^^^^^^^^^^^^^^^^^^^^
  File "/home/airflow/.local/lib/python3.12/site-packages/airflow/models/baseoperator.py", line 400, in wrapper
    return func(self, *args, **kwargs)
           ^^^^^^^^^^^^^^^^^^^^^^^^^^^
  File "/home/airflow/.local/lib/python3.12/site-packages/airflow/operators/bash.py", line 243, in execute
    raise AirflowException(
airflow.exceptions.AirflowException: Bash command failed. The command returned a non-zero exit code 1.
[2024-05-16T11:19:50.996+0000] {taskinstance.py:1205} INFO - Marking task as UP_FOR_RETRY. dag_id=dag_tables, task_id=import_table3, execution_date=20240514T000000, start_date=20240516T111950, end_date=20240516T111950
[2024-05-16T11:19:51.008+0000] {standard_task_runner.py:110} ERROR - Failed to execute job 421 for task import_table3 (Bash command failed. The command returned a non-zero exit code 1.; 344)
[2024-05-16T11:19:51.030+0000] {local_task_job_runner.py:240} INFO - Task exited with return code 1
[2024-05-16T11:19:51.049+0000] {taskinstance.py:3482} INFO - 0 downstream tasks scheduled from follow-on schedule check
[2024-05-16T11:19:51.052+0000] {local_task_job_runner.py:222} INFO - ::endgroup::
