[2024-05-16T11:19:50.664+0000] {local_task_job_runner.py:120} INFO - ::group::Pre task execution logs
[2024-05-16T11:19:50.685+0000] {taskinstance.py:2073} INFO - Dependencies all met for dep_context=non-requeueable deps ti=<TaskInstance: dag_tables.import_table4 scheduled__2024-05-08T00:00:00+00:00 [queued]>
[2024-05-16T11:19:50.693+0000] {taskinstance.py:2073} INFO - Dependencies all met for dep_context=requeueable deps ti=<TaskInstance: dag_tables.import_table4 scheduled__2024-05-08T00:00:00+00:00 [queued]>
[2024-05-16T11:19:50.697+0000] {taskinstance.py:2303} INFO - Starting attempt 1 of 6
[2024-05-16T11:19:50.713+0000] {taskinstance.py:2327} INFO - Executing <Task(BashOperator): import_table4> on 2024-05-08 00:00:00+00:00
[2024-05-16T11:19:50.720+0000] {logging_mixin.py:188} WARNING - /home/***/.local/lib/python3.12/site-packages/***/task/task_runner/standard_task_runner.py:61 DeprecationWarning: This process (pid=333) is multi-threaded, use of fork() may lead to deadlocks in the child.
[2024-05-16T11:19:50.721+0000] {standard_task_runner.py:63} INFO - Started process 345 to run task
[2024-05-16T11:19:50.723+0000] {standard_task_runner.py:90} INFO - Running: ['***', 'tasks', 'run', 'dag_tables', 'import_table4', 'scheduled__2024-05-08T00:00:00+00:00', '--job-id', '424', '--raw', '--subdir', 'DAGS_FOLDER/dag_mysql.py', '--cfg-path', '/tmp/tmpbwyjbm3r']
[2024-05-16T11:19:50.728+0000] {standard_task_runner.py:91} INFO - Job 424: Subtask import_table4
[2024-05-16T11:19:50.767+0000] {task_command.py:426} INFO - Running <TaskInstance: dag_tables.import_table4 scheduled__2024-05-08T00:00:00+00:00 [running]> on host 7084a6d88d3b
[2024-05-16T11:19:50.869+0000] {taskinstance.py:2644} INFO - Exporting env vars: AIRFLOW_CTX_DAG_OWNER='bses' AIRFLOW_CTX_DAG_ID='dag_tables' AIRFLOW_CTX_TASK_ID='import_table4' AIRFLOW_CTX_EXECUTION_DATE='2024-05-08T00:00:00+00:00' AIRFLOW_CTX_TRY_NUMBER='1' AIRFLOW_CTX_DAG_RUN_ID='scheduled__2024-05-08T00:00:00+00:00'
[2024-05-16T11:19:50.870+0000] {taskinstance.py:430} INFO - ::endgroup::
[2024-05-16T11:19:50.878+0000] {subprocess.py:63} INFO - Tmp dir root location: /tmp
[2024-05-16T11:19:50.879+0000] {subprocess.py:75} INFO - Running command: ['/usr/bin/bash', '-c', '\n                mysql -h host.docker.internal -u root --password=12345678 test < /opt/***/dags/report_table.sql;\n                ']
[2024-05-16T11:19:50.894+0000] {subprocess.py:86} INFO - Output:
[2024-05-16T11:19:50.945+0000] {subprocess.py:93} INFO - ERROR 1050 (42S01) at line 8: Table 'customer_profile' already exists
[2024-05-16T11:19:50.947+0000] {subprocess.py:97} INFO - Command exited with return code 1
[2024-05-16T11:19:50.948+0000] {taskinstance.py:441} INFO - ::group::Post task execution logs
[2024-05-16T11:19:50.957+0000] {taskinstance.py:2890} ERROR - Task failed with exception
Traceback (most recent call last):
  File "/home/airflow/.local/lib/python3.12/site-packages/airflow/models/taskinstance.py", line 465, in _execute_task
    result = _execute_callable(context=context, **execute_callable_kwargs)
             ^^^^^^^^^^^^^^^^^^^^^^^^^^^^^^^^^^^^^^^^^^^^^^^^^^^^^^^^^^^^^
  File "/home/airflow/.local/lib/python3.12/site-packages/airflow/models/taskinstance.py", line 432, in _execute_callable
    return execute_callable(context=context, **execute_callable_kwargs)
           ^^^^^^^^^^^^^^^^^^^^^^^^^^^^^^^^^^^^^^^^^^^^^^^^^^^^^^^^^^^^
  File "/home/airflow/.local/lib/python3.12/site-packages/airflow/models/baseoperator.py", line 400, in wrapper
    return func(self, *args, **kwargs)
           ^^^^^^^^^^^^^^^^^^^^^^^^^^^
  File "/home/airflow/.local/lib/python3.12/site-packages/airflow/operators/bash.py", line 243, in execute
    raise AirflowException(
airflow.exceptions.AirflowException: Bash command failed. The command returned a non-zero exit code 1.
[2024-05-16T11:19:50.960+0000] {taskinstance.py:1205} INFO - Marking task as UP_FOR_RETRY. dag_id=dag_tables, task_id=import_table4, execution_date=20240508T000000, start_date=20240516T111950, end_date=20240516T111950
[2024-05-16T11:19:50.978+0000] {standard_task_runner.py:110} ERROR - Failed to execute job 424 for task import_table4 (Bash command failed. The command returned a non-zero exit code 1.; 345)
[2024-05-16T11:19:51.032+0000] {local_task_job_runner.py:240} INFO - Task exited with return code 1
[2024-05-16T11:19:51.062+0000] {taskinstance.py:3482} INFO - 0 downstream tasks scheduled from follow-on schedule check
[2024-05-16T11:19:51.072+0000] {local_task_job_runner.py:222} INFO - ::endgroup::
[2024-05-16T11:32:52.259+0000] {local_task_job_runner.py:120} INFO - ::group::Pre task execution logs
[2024-05-16T11:32:52.275+0000] {taskinstance.py:2073} INFO - Dependencies all met for dep_context=non-requeueable deps ti=<TaskInstance: dag_tables.import_table4 scheduled__2024-05-08T00:00:00+00:00 [queued]>
[2024-05-16T11:32:52.279+0000] {taskinstance.py:2073} INFO - Dependencies all met for dep_context=requeueable deps ti=<TaskInstance: dag_tables.import_table4 scheduled__2024-05-08T00:00:00+00:00 [queued]>
[2024-05-16T11:32:52.280+0000] {taskinstance.py:2303} INFO - Starting attempt 1 of 6
[2024-05-16T11:32:52.285+0000] {taskinstance.py:2327} INFO - Executing <Task(BashOperator): import_table4> on 2024-05-08 00:00:00+00:00
[2024-05-16T11:32:52.289+0000] {logging_mixin.py:188} WARNING - /home/***/.local/lib/python3.12/site-packages/***/task/task_runner/standard_task_runner.py:61 DeprecationWarning: This process (pid=1150) is multi-threaded, use of fork() may lead to deadlocks in the child.
[2024-05-16T11:32:52.290+0000] {standard_task_runner.py:63} INFO - Started process 1151 to run task
[2024-05-16T11:32:52.289+0000] {standard_task_runner.py:90} INFO - Running: ['***', 'tasks', 'run', 'dag_tables', 'import_table4', 'scheduled__2024-05-08T00:00:00+00:00', '--job-id', '544', '--raw', '--subdir', 'DAGS_FOLDER/dag_mysql.py', '--cfg-path', '/tmp/tmpt04ea78a']
[2024-05-16T11:32:52.291+0000] {standard_task_runner.py:91} INFO - Job 544: Subtask import_table4
[2024-05-16T11:32:52.315+0000] {task_command.py:426} INFO - Running <TaskInstance: dag_tables.import_table4 scheduled__2024-05-08T00:00:00+00:00 [running]> on host 7084a6d88d3b
[2024-05-16T11:32:52.352+0000] {taskinstance.py:2644} INFO - Exporting env vars: AIRFLOW_CTX_DAG_OWNER='bses' AIRFLOW_CTX_DAG_ID='dag_tables' AIRFLOW_CTX_TASK_ID='import_table4' AIRFLOW_CTX_EXECUTION_DATE='2024-05-08T00:00:00+00:00' AIRFLOW_CTX_TRY_NUMBER='1' AIRFLOW_CTX_DAG_RUN_ID='scheduled__2024-05-08T00:00:00+00:00'
[2024-05-16T11:32:52.353+0000] {taskinstance.py:430} INFO - ::endgroup::
[2024-05-16T11:32:52.358+0000] {subprocess.py:63} INFO - Tmp dir root location: /tmp
[2024-05-16T11:32:52.358+0000] {subprocess.py:75} INFO - Running command: ['/usr/bin/bash', '-c', '\n                mysql -h host.docker.internal -u root --password=12345678 test < /opt/***/dags/report_table.sql\n                ']
[2024-05-16T11:32:52.362+0000] {subprocess.py:86} INFO - Output:
[2024-05-16T11:32:52.394+0000] {subprocess.py:93} INFO - ERROR 1050 (42S01) at line 8: Table 'customer_profile' already exists
[2024-05-16T11:32:52.396+0000] {subprocess.py:97} INFO - Command exited with return code 1
[2024-05-16T11:32:52.396+0000] {taskinstance.py:441} INFO - ::group::Post task execution logs
[2024-05-16T11:32:52.402+0000] {taskinstance.py:2890} ERROR - Task failed with exception
Traceback (most recent call last):
  File "/home/airflow/.local/lib/python3.12/site-packages/airflow/models/taskinstance.py", line 465, in _execute_task
    result = _execute_callable(context=context, **execute_callable_kwargs)
             ^^^^^^^^^^^^^^^^^^^^^^^^^^^^^^^^^^^^^^^^^^^^^^^^^^^^^^^^^^^^^
  File "/home/airflow/.local/lib/python3.12/site-packages/airflow/models/taskinstance.py", line 432, in _execute_callable
    return execute_callable(context=context, **execute_callable_kwargs)
           ^^^^^^^^^^^^^^^^^^^^^^^^^^^^^^^^^^^^^^^^^^^^^^^^^^^^^^^^^^^^
  File "/home/airflow/.local/lib/python3.12/site-packages/airflow/models/baseoperator.py", line 400, in wrapper
    return func(self, *args, **kwargs)
           ^^^^^^^^^^^^^^^^^^^^^^^^^^^
  File "/home/airflow/.local/lib/python3.12/site-packages/airflow/operators/bash.py", line 243, in execute
    raise AirflowException(
airflow.exceptions.AirflowException: Bash command failed. The command returned a non-zero exit code 1.
[2024-05-16T11:32:52.405+0000] {taskinstance.py:1205} INFO - Marking task as UP_FOR_RETRY. dag_id=dag_tables, task_id=import_table4, execution_date=20240508T000000, start_date=20240516T113252, end_date=20240516T113252
[2024-05-16T11:32:52.411+0000] {standard_task_runner.py:110} ERROR - Failed to execute job 544 for task import_table4 (Bash command failed. The command returned a non-zero exit code 1.; 1151)
[2024-05-16T11:32:52.429+0000] {local_task_job_runner.py:240} INFO - Task exited with return code 1
[2024-05-16T11:32:52.437+0000] {taskinstance.py:3482} INFO - 0 downstream tasks scheduled from follow-on schedule check
[2024-05-16T11:32:52.438+0000] {local_task_job_runner.py:222} INFO - ::endgroup::
