[2024-05-04T10:23:53.536+0000] {local_task_job_runner.py:120} INFO - ::group::Pre task execution logs
[2024-05-04T10:23:53.551+0000] {taskinstance.py:2073} INFO - Dependencies all met for dep_context=non-requeueable deps ti=<TaskInstance: dag_mysql.task1 scheduled__2024-05-02T00:00:00+00:00 [queued]>
[2024-05-04T10:23:53.556+0000] {taskinstance.py:2073} INFO - Dependencies all met for dep_context=requeueable deps ti=<TaskInstance: dag_mysql.task1 scheduled__2024-05-02T00:00:00+00:00 [queued]>
[2024-05-04T10:23:53.556+0000] {taskinstance.py:2303} INFO - Starting attempt 1 of 6
[2024-05-04T10:23:53.562+0000] {taskinstance.py:2327} INFO - Executing <Task(MySqlOperator): task1> on 2024-05-02 00:00:00+00:00
[2024-05-04T10:23:53.565+0000] {standard_task_runner.py:90} INFO - Running: ['***', 'tasks', 'run', 'dag_mysql', 'task1', 'scheduled__2024-05-02T00:00:00+00:00', '--job-id', '15', '--raw', '--subdir', 'DAGS_FOLDER/dag_mysql.py', '--cfg-path', '/tmp/tmpnz4gchec']
[2024-05-04T10:23:53.567+0000] {logging_mixin.py:188} WARNING - /home/***/.local/lib/python3.12/site-packages/***/task/task_runner/standard_task_runner.py:61 DeprecationWarning: This process (pid=811) is multi-threaded, use of fork() may lead to deadlocks in the child.
[2024-05-04T10:23:53.567+0000] {standard_task_runner.py:91} INFO - Job 15: Subtask task1
[2024-05-04T10:23:53.567+0000] {standard_task_runner.py:63} INFO - Started process 814 to run task
[2024-05-04T10:23:53.588+0000] {task_command.py:426} INFO - Running <TaskInstance: dag_mysql.task1 scheduled__2024-05-02T00:00:00+00:00 [running]> on host 97b2d875d020
[2024-05-04T10:23:53.626+0000] {taskinstance.py:2644} INFO - Exporting env vars: AIRFLOW_CTX_DAG_OWNER='bses' AIRFLOW_CTX_DAG_ID='dag_mysql' AIRFLOW_CTX_TASK_ID='task1' AIRFLOW_CTX_EXECUTION_DATE='2024-05-02T00:00:00+00:00' AIRFLOW_CTX_TRY_NUMBER='1' AIRFLOW_CTX_DAG_RUN_ID='scheduled__2024-05-02T00:00:00+00:00'
[2024-05-04T10:23:53.627+0000] {taskinstance.py:430} INFO - ::endgroup::
[2024-05-04T10:23:53.634+0000] {sql.py:276} INFO - Executing: SHOW DATABASES;
[2024-05-04T10:23:53.638+0000] {base.py:84} INFO - Using connection ID 'mysql_local' for task execution.
[2024-05-04T10:23:53.642+0000] {base.py:84} INFO - Using connection ID 'mysql_local' for task execution.
[2024-05-04T10:23:53.653+0000] {taskinstance.py:441} INFO - ::group::Post task execution logs
[2024-05-04T10:23:53.654+0000] {taskinstance.py:2890} ERROR - Task failed with exception
Traceback (most recent call last):
  File "/home/airflow/.local/lib/python3.12/site-packages/airflow/models/taskinstance.py", line 465, in _execute_task
    result = _execute_callable(context=context, **execute_callable_kwargs)
             ^^^^^^^^^^^^^^^^^^^^^^^^^^^^^^^^^^^^^^^^^^^^^^^^^^^^^^^^^^^^^
  File "/home/airflow/.local/lib/python3.12/site-packages/airflow/models/taskinstance.py", line 432, in _execute_callable
    return execute_callable(context=context, **execute_callable_kwargs)
           ^^^^^^^^^^^^^^^^^^^^^^^^^^^^^^^^^^^^^^^^^^^^^^^^^^^^^^^^^^^^
  File "/home/airflow/.local/lib/python3.12/site-packages/airflow/models/baseoperator.py", line 400, in wrapper
    return func(self, *args, **kwargs)
           ^^^^^^^^^^^^^^^^^^^^^^^^^^^
  File "/home/airflow/.local/lib/python3.12/site-packages/airflow/providers/common/sql/operators/sql.py", line 282, in execute
    output = hook.run(
             ^^^^^^^^^
  File "/home/airflow/.local/lib/python3.12/site-packages/airflow/providers/common/sql/hooks/sql.py", line 397, in run
    with closing(self.get_conn()) as conn:
                 ^^^^^^^^^^^^^^^
  File "/home/airflow/.local/lib/python3.12/site-packages/airflow/providers/mysql/hooks/mysql.py", line 195, in get_conn
    return MySQLdb.connect(**conn_config)
           ^^^^^^^^^^^^^^^^^^^^^^^^^^^^^^
  File "/home/airflow/.local/lib/python3.12/site-packages/MySQLdb/__init__.py", line 121, in Connect
    return Connection(*args, **kwargs)
           ^^^^^^^^^^^^^^^^^^^^^^^^^^^
  File "/home/airflow/.local/lib/python3.12/site-packages/MySQLdb/connections.py", line 195, in __init__
    super().__init__(*args, **kwargs2)
MySQLdb.OperationalError: (2002, "Can't connect to server on 'host.docker.internal' (115)")
[2024-05-04T10:23:53.660+0000] {taskinstance.py:1205} INFO - Marking task as UP_FOR_RETRY. dag_id=dag_mysql, task_id=task1, execution_date=20240502T000000, start_date=20240504T102353, end_date=20240504T102353
[2024-05-04T10:23:53.666+0000] {standard_task_runner.py:110} ERROR - Failed to execute job 15 for task task1 ((2002, "Can't connect to server on 'host.docker.internal' (115)"); 814)
[2024-05-04T10:23:53.705+0000] {local_task_job_runner.py:240} INFO - Task exited with return code 1
[2024-05-04T10:23:53.713+0000] {taskinstance.py:3482} INFO - 0 downstream tasks scheduled from follow-on schedule check
[2024-05-04T10:23:53.714+0000] {local_task_job_runner.py:222} INFO - ::endgroup::
[2024-05-04T10:26:56.810+0000] {local_task_job_runner.py:120} INFO - ::group::Pre task execution logs
[2024-05-04T10:26:56.827+0000] {taskinstance.py:2073} INFO - Dependencies all met for dep_context=non-requeueable deps ti=<TaskInstance: dag_mysql.task1 scheduled__2024-05-02T00:00:00+00:00 [queued]>
[2024-05-04T10:26:56.831+0000] {taskinstance.py:2073} INFO - Dependencies all met for dep_context=requeueable deps ti=<TaskInstance: dag_mysql.task1 scheduled__2024-05-02T00:00:00+00:00 [queued]>
[2024-05-04T10:26:56.832+0000] {taskinstance.py:2303} INFO - Starting attempt 1 of 6
[2024-05-04T10:26:56.839+0000] {taskinstance.py:2327} INFO - Executing <Task(MySqlOperator): task1> on 2024-05-02 00:00:00+00:00
[2024-05-04T10:26:56.843+0000] {standard_task_runner.py:90} INFO - Running: ['***', 'tasks', 'run', 'dag_mysql', 'task1', 'scheduled__2024-05-02T00:00:00+00:00', '--job-id', '18', '--raw', '--subdir', 'DAGS_FOLDER/dag_mysql.py', '--cfg-path', '/tmp/tmpwvc_34_p']
[2024-05-04T10:26:56.846+0000] {standard_task_runner.py:91} INFO - Job 18: Subtask task1
[2024-05-04T10:26:56.845+0000] {logging_mixin.py:188} WARNING - /home/***/.local/lib/python3.12/site-packages/***/task/task_runner/standard_task_runner.py:61 DeprecationWarning: This process (pid=1002) is multi-threaded, use of fork() may lead to deadlocks in the child.
[2024-05-04T10:26:56.846+0000] {standard_task_runner.py:63} INFO - Started process 1005 to run task
[2024-05-04T10:26:56.890+0000] {task_command.py:426} INFO - Running <TaskInstance: dag_mysql.task1 scheduled__2024-05-02T00:00:00+00:00 [running]> on host 97b2d875d020
[2024-05-04T10:26:56.946+0000] {taskinstance.py:2644} INFO - Exporting env vars: AIRFLOW_CTX_DAG_OWNER='bses' AIRFLOW_CTX_DAG_ID='dag_mysql' AIRFLOW_CTX_TASK_ID='task1' AIRFLOW_CTX_EXECUTION_DATE='2024-05-02T00:00:00+00:00' AIRFLOW_CTX_TRY_NUMBER='1' AIRFLOW_CTX_DAG_RUN_ID='scheduled__2024-05-02T00:00:00+00:00'
[2024-05-04T10:26:56.946+0000] {taskinstance.py:430} INFO - ::endgroup::
[2024-05-04T10:26:56.956+0000] {sql.py:276} INFO - Executing: SHOW DATABASES;
[2024-05-04T10:26:56.960+0000] {base.py:84} INFO - Using connection ID 'mysql_local' for task execution.
[2024-05-04T10:26:56.964+0000] {base.py:84} INFO - Using connection ID 'mysql_local' for task execution.
[2024-05-04T10:26:56.970+0000] {taskinstance.py:441} INFO - ::group::Post task execution logs
[2024-05-04T10:26:56.971+0000] {taskinstance.py:2890} ERROR - Task failed with exception
Traceback (most recent call last):
  File "/home/airflow/.local/lib/python3.12/site-packages/airflow/models/taskinstance.py", line 465, in _execute_task
    result = _execute_callable(context=context, **execute_callable_kwargs)
             ^^^^^^^^^^^^^^^^^^^^^^^^^^^^^^^^^^^^^^^^^^^^^^^^^^^^^^^^^^^^^
  File "/home/airflow/.local/lib/python3.12/site-packages/airflow/models/taskinstance.py", line 432, in _execute_callable
    return execute_callable(context=context, **execute_callable_kwargs)
           ^^^^^^^^^^^^^^^^^^^^^^^^^^^^^^^^^^^^^^^^^^^^^^^^^^^^^^^^^^^^
  File "/home/airflow/.local/lib/python3.12/site-packages/airflow/models/baseoperator.py", line 400, in wrapper
    return func(self, *args, **kwargs)
           ^^^^^^^^^^^^^^^^^^^^^^^^^^^
  File "/home/airflow/.local/lib/python3.12/site-packages/airflow/providers/common/sql/operators/sql.py", line 282, in execute
    output = hook.run(
             ^^^^^^^^^
  File "/home/airflow/.local/lib/python3.12/site-packages/airflow/providers/common/sql/hooks/sql.py", line 397, in run
    with closing(self.get_conn()) as conn:
                 ^^^^^^^^^^^^^^^
  File "/home/airflow/.local/lib/python3.12/site-packages/airflow/providers/mysql/hooks/mysql.py", line 195, in get_conn
    return MySQLdb.connect(**conn_config)
           ^^^^^^^^^^^^^^^^^^^^^^^^^^^^^^
  File "/home/airflow/.local/lib/python3.12/site-packages/MySQLdb/__init__.py", line 121, in Connect
    return Connection(*args, **kwargs)
           ^^^^^^^^^^^^^^^^^^^^^^^^^^^
  File "/home/airflow/.local/lib/python3.12/site-packages/MySQLdb/connections.py", line 195, in __init__
    super().__init__(*args, **kwargs2)
MySQLdb.OperationalError: (1524, "Plugin 'mysql_native_password' is not loaded")
[2024-05-04T10:26:56.976+0000] {taskinstance.py:1205} INFO - Marking task as UP_FOR_RETRY. dag_id=dag_mysql, task_id=task1, execution_date=20240502T000000, start_date=20240504T102656, end_date=20240504T102656
[2024-05-04T10:26:56.982+0000] {standard_task_runner.py:110} ERROR - Failed to execute job 18 for task task1 ((1524, "Plugin 'mysql_native_password' is not loaded"); 1005)
[2024-05-04T10:26:56.985+0000] {local_task_job_runner.py:240} INFO - Task exited with return code 1
[2024-05-04T10:26:56.993+0000] {taskinstance.py:3482} INFO - 0 downstream tasks scheduled from follow-on schedule check
[2024-05-04T10:26:56.995+0000] {local_task_job_runner.py:222} INFO - ::endgroup::
[2024-05-04T10:29:29.171+0000] {local_task_job_runner.py:120} INFO - ::group::Pre task execution logs
[2024-05-04T10:29:29.186+0000] {taskinstance.py:2073} INFO - Dependencies all met for dep_context=non-requeueable deps ti=<TaskInstance: dag_mysql.task1 scheduled__2024-05-02T00:00:00+00:00 [queued]>
[2024-05-04T10:29:29.190+0000] {taskinstance.py:2073} INFO - Dependencies all met for dep_context=requeueable deps ti=<TaskInstance: dag_mysql.task1 scheduled__2024-05-02T00:00:00+00:00 [queued]>
[2024-05-04T10:29:29.191+0000] {taskinstance.py:2303} INFO - Starting attempt 1 of 6
[2024-05-04T10:29:29.198+0000] {taskinstance.py:2327} INFO - Executing <Task(MySqlOperator): task1> on 2024-05-02 00:00:00+00:00
[2024-05-04T10:29:29.201+0000] {standard_task_runner.py:90} INFO - Running: ['***', 'tasks', 'run', 'dag_mysql', 'task1', 'scheduled__2024-05-02T00:00:00+00:00', '--job-id', '21', '--raw', '--subdir', 'DAGS_FOLDER/dag_mysql.py', '--cfg-path', '/tmp/tmpxu1t0fmt']
[2024-05-04T10:29:29.202+0000] {logging_mixin.py:188} WARNING - /home/***/.local/lib/python3.12/site-packages/***/task/task_runner/standard_task_runner.py:61 DeprecationWarning: This process (pid=1161) is multi-threaded, use of fork() may lead to deadlocks in the child.
[2024-05-04T10:29:29.203+0000] {standard_task_runner.py:91} INFO - Job 21: Subtask task1
[2024-05-04T10:29:29.203+0000] {standard_task_runner.py:63} INFO - Started process 1164 to run task
[2024-05-04T10:29:29.226+0000] {task_command.py:426} INFO - Running <TaskInstance: dag_mysql.task1 scheduled__2024-05-02T00:00:00+00:00 [running]> on host 97b2d875d020
[2024-05-04T10:29:29.267+0000] {taskinstance.py:2644} INFO - Exporting env vars: AIRFLOW_CTX_DAG_OWNER='bses' AIRFLOW_CTX_DAG_ID='dag_mysql' AIRFLOW_CTX_TASK_ID='task1' AIRFLOW_CTX_EXECUTION_DATE='2024-05-02T00:00:00+00:00' AIRFLOW_CTX_TRY_NUMBER='1' AIRFLOW_CTX_DAG_RUN_ID='scheduled__2024-05-02T00:00:00+00:00'
[2024-05-04T10:29:29.268+0000] {taskinstance.py:430} INFO - ::endgroup::
[2024-05-04T10:29:29.276+0000] {sql.py:276} INFO - Executing: SHOW DATABASES;
[2024-05-04T10:29:29.280+0000] {base.py:84} INFO - Using connection ID 'mysql_local' for task execution.
[2024-05-04T10:29:29.285+0000] {base.py:84} INFO - Using connection ID 'mysql_local' for task execution.
[2024-05-04T10:29:29.292+0000] {taskinstance.py:441} INFO - ::group::Post task execution logs
[2024-05-04T10:29:29.292+0000] {taskinstance.py:2890} ERROR - Task failed with exception
Traceback (most recent call last):
  File "/home/airflow/.local/lib/python3.12/site-packages/airflow/models/taskinstance.py", line 465, in _execute_task
    result = _execute_callable(context=context, **execute_callable_kwargs)
             ^^^^^^^^^^^^^^^^^^^^^^^^^^^^^^^^^^^^^^^^^^^^^^^^^^^^^^^^^^^^^
  File "/home/airflow/.local/lib/python3.12/site-packages/airflow/models/taskinstance.py", line 432, in _execute_callable
    return execute_callable(context=context, **execute_callable_kwargs)
           ^^^^^^^^^^^^^^^^^^^^^^^^^^^^^^^^^^^^^^^^^^^^^^^^^^^^^^^^^^^^
  File "/home/airflow/.local/lib/python3.12/site-packages/airflow/models/baseoperator.py", line 400, in wrapper
    return func(self, *args, **kwargs)
           ^^^^^^^^^^^^^^^^^^^^^^^^^^^
  File "/home/airflow/.local/lib/python3.12/site-packages/airflow/providers/common/sql/operators/sql.py", line 282, in execute
    output = hook.run(
             ^^^^^^^^^
  File "/home/airflow/.local/lib/python3.12/site-packages/airflow/providers/common/sql/hooks/sql.py", line 397, in run
    with closing(self.get_conn()) as conn:
                 ^^^^^^^^^^^^^^^
  File "/home/airflow/.local/lib/python3.12/site-packages/airflow/providers/mysql/hooks/mysql.py", line 195, in get_conn
    return MySQLdb.connect(**conn_config)
           ^^^^^^^^^^^^^^^^^^^^^^^^^^^^^^
  File "/home/airflow/.local/lib/python3.12/site-packages/MySQLdb/__init__.py", line 121, in Connect
    return Connection(*args, **kwargs)
           ^^^^^^^^^^^^^^^^^^^^^^^^^^^
  File "/home/airflow/.local/lib/python3.12/site-packages/MySQLdb/connections.py", line 195, in __init__
    super().__init__(*args, **kwargs2)
MySQLdb.OperationalError: (1049, "Unknown database 'test'")
[2024-05-04T10:29:29.298+0000] {taskinstance.py:1205} INFO - Marking task as UP_FOR_RETRY. dag_id=dag_mysql, task_id=task1, execution_date=20240502T000000, start_date=20240504T102929, end_date=20240504T102929
[2024-05-04T10:29:29.304+0000] {standard_task_runner.py:110} ERROR - Failed to execute job 21 for task task1 ((1049, "Unknown database 'test'"); 1164)
[2024-05-04T10:29:29.346+0000] {local_task_job_runner.py:240} INFO - Task exited with return code 1
[2024-05-04T10:29:29.354+0000] {taskinstance.py:3482} INFO - 0 downstream tasks scheduled from follow-on schedule check
[2024-05-04T10:29:29.355+0000] {local_task_job_runner.py:222} INFO - ::endgroup::
[2024-05-04T10:31:41.261+0000] {local_task_job_runner.py:120} INFO - ::group::Pre task execution logs
[2024-05-04T10:31:41.276+0000] {taskinstance.py:2073} INFO - Dependencies all met for dep_context=non-requeueable deps ti=<TaskInstance: dag_mysql.task1 scheduled__2024-05-02T00:00:00+00:00 [queued]>
[2024-05-04T10:31:41.279+0000] {taskinstance.py:2073} INFO - Dependencies all met for dep_context=requeueable deps ti=<TaskInstance: dag_mysql.task1 scheduled__2024-05-02T00:00:00+00:00 [queued]>
[2024-05-04T10:31:41.280+0000] {taskinstance.py:2303} INFO - Starting attempt 1 of 6
[2024-05-04T10:31:41.288+0000] {taskinstance.py:2327} INFO - Executing <Task(MySqlOperator): task1> on 2024-05-02 00:00:00+00:00
[2024-05-04T10:31:41.292+0000] {standard_task_runner.py:90} INFO - Running: ['***', 'tasks', 'run', 'dag_mysql', 'task1', 'scheduled__2024-05-02T00:00:00+00:00', '--job-id', '26', '--raw', '--subdir', 'DAGS_FOLDER/dag_mysql.py', '--cfg-path', '/tmp/tmpkc1183t0']
[2024-05-04T10:31:41.293+0000] {logging_mixin.py:188} WARNING - /home/***/.local/lib/python3.12/site-packages/***/task/task_runner/standard_task_runner.py:61 DeprecationWarning: This process (pid=222) is multi-threaded, use of fork() may lead to deadlocks in the child.
[2024-05-04T10:31:41.294+0000] {standard_task_runner.py:91} INFO - Job 26: Subtask task1
[2024-05-04T10:31:41.294+0000] {standard_task_runner.py:63} INFO - Started process 225 to run task
[2024-05-04T10:31:41.318+0000] {task_command.py:426} INFO - Running <TaskInstance: dag_mysql.task1 scheduled__2024-05-02T00:00:00+00:00 [running]> on host fcbb02d87472
[2024-05-04T10:31:41.359+0000] {taskinstance.py:2644} INFO - Exporting env vars: AIRFLOW_CTX_DAG_OWNER='bses' AIRFLOW_CTX_DAG_ID='dag_mysql' AIRFLOW_CTX_TASK_ID='task1' AIRFLOW_CTX_EXECUTION_DATE='2024-05-02T00:00:00+00:00' AIRFLOW_CTX_TRY_NUMBER='1' AIRFLOW_CTX_DAG_RUN_ID='scheduled__2024-05-02T00:00:00+00:00'
[2024-05-04T10:31:41.359+0000] {taskinstance.py:430} INFO - ::endgroup::
[2024-05-04T10:31:41.368+0000] {sql.py:276} INFO - Executing: SHOW DATABASES;
[2024-05-04T10:31:41.372+0000] {base.py:84} INFO - Using connection ID 'mysql_local' for task execution.
[2024-05-04T10:31:41.377+0000] {base.py:84} INFO - Using connection ID 'mysql_local' for task execution.
[2024-05-04T10:31:41.383+0000] {taskinstance.py:441} INFO - ::group::Post task execution logs
[2024-05-04T10:31:41.384+0000] {taskinstance.py:2890} ERROR - Task failed with exception
Traceback (most recent call last):
  File "/home/airflow/.local/lib/python3.12/site-packages/airflow/models/taskinstance.py", line 465, in _execute_task
    result = _execute_callable(context=context, **execute_callable_kwargs)
             ^^^^^^^^^^^^^^^^^^^^^^^^^^^^^^^^^^^^^^^^^^^^^^^^^^^^^^^^^^^^^
  File "/home/airflow/.local/lib/python3.12/site-packages/airflow/models/taskinstance.py", line 432, in _execute_callable
    return execute_callable(context=context, **execute_callable_kwargs)
           ^^^^^^^^^^^^^^^^^^^^^^^^^^^^^^^^^^^^^^^^^^^^^^^^^^^^^^^^^^^^
  File "/home/airflow/.local/lib/python3.12/site-packages/airflow/models/baseoperator.py", line 400, in wrapper
    return func(self, *args, **kwargs)
           ^^^^^^^^^^^^^^^^^^^^^^^^^^^
  File "/home/airflow/.local/lib/python3.12/site-packages/airflow/providers/common/sql/operators/sql.py", line 282, in execute
    output = hook.run(
             ^^^^^^^^^
  File "/home/airflow/.local/lib/python3.12/site-packages/airflow/providers/common/sql/hooks/sql.py", line 397, in run
    with closing(self.get_conn()) as conn:
                 ^^^^^^^^^^^^^^^
  File "/home/airflow/.local/lib/python3.12/site-packages/airflow/providers/mysql/hooks/mysql.py", line 195, in get_conn
    return MySQLdb.connect(**conn_config)
           ^^^^^^^^^^^^^^^^^^^^^^^^^^^^^^
  File "/home/airflow/.local/lib/python3.12/site-packages/MySQLdb/__init__.py", line 121, in Connect
    return Connection(*args, **kwargs)
           ^^^^^^^^^^^^^^^^^^^^^^^^^^^
  File "/home/airflow/.local/lib/python3.12/site-packages/MySQLdb/connections.py", line 195, in __init__
    super().__init__(*args, **kwargs2)
MySQLdb.OperationalError: (1049, "Unknown database 'test'")
[2024-05-04T10:31:41.389+0000] {taskinstance.py:1205} INFO - Marking task as UP_FOR_RETRY. dag_id=dag_mysql, task_id=task1, execution_date=20240502T000000, start_date=20240504T103141, end_date=20240504T103141
[2024-05-04T10:31:41.394+0000] {standard_task_runner.py:110} ERROR - Failed to execute job 26 for task task1 ((1049, "Unknown database 'test'"); 225)
[2024-05-04T10:31:41.434+0000] {local_task_job_runner.py:240} INFO - Task exited with return code 1
[2024-05-04T10:31:41.443+0000] {taskinstance.py:3482} INFO - 0 downstream tasks scheduled from follow-on schedule check
[2024-05-04T10:31:41.444+0000] {local_task_job_runner.py:222} INFO - ::endgroup::
[2024-05-04T10:34:15.098+0000] {local_task_job_runner.py:120} INFO - ::group::Pre task execution logs
[2024-05-04T10:34:15.112+0000] {taskinstance.py:2073} INFO - Dependencies all met for dep_context=non-requeueable deps ti=<TaskInstance: dag_mysql.task1 scheduled__2024-05-02T00:00:00+00:00 [queued]>
[2024-05-04T10:34:15.116+0000] {taskinstance.py:2073} INFO - Dependencies all met for dep_context=requeueable deps ti=<TaskInstance: dag_mysql.task1 scheduled__2024-05-02T00:00:00+00:00 [queued]>
[2024-05-04T10:34:15.117+0000] {taskinstance.py:2303} INFO - Starting attempt 1 of 6
[2024-05-04T10:34:15.124+0000] {taskinstance.py:2327} INFO - Executing <Task(MySqlOperator): task1> on 2024-05-02 00:00:00+00:00
[2024-05-04T10:34:15.128+0000] {standard_task_runner.py:90} INFO - Running: ['***', 'tasks', 'run', 'dag_mysql', 'task1', 'scheduled__2024-05-02T00:00:00+00:00', '--job-id', '31', '--raw', '--subdir', 'DAGS_FOLDER/dag_mysql.py', '--cfg-path', '/tmp/tmp774q_w46']
[2024-05-04T10:34:15.129+0000] {logging_mixin.py:188} WARNING - /home/***/.local/lib/python3.12/site-packages/***/task/task_runner/standard_task_runner.py:61 DeprecationWarning: This process (pid=197) is multi-threaded, use of fork() may lead to deadlocks in the child.
[2024-05-04T10:34:15.129+0000] {standard_task_runner.py:91} INFO - Job 31: Subtask task1
[2024-05-04T10:34:15.130+0000] {standard_task_runner.py:63} INFO - Started process 200 to run task
[2024-05-04T10:34:15.150+0000] {task_command.py:426} INFO - Running <TaskInstance: dag_mysql.task1 scheduled__2024-05-02T00:00:00+00:00 [running]> on host f85b7a0b58b5
[2024-05-04T10:34:15.185+0000] {taskinstance.py:2644} INFO - Exporting env vars: AIRFLOW_CTX_DAG_OWNER='bses' AIRFLOW_CTX_DAG_ID='dag_mysql' AIRFLOW_CTX_TASK_ID='task1' AIRFLOW_CTX_EXECUTION_DATE='2024-05-02T00:00:00+00:00' AIRFLOW_CTX_TRY_NUMBER='1' AIRFLOW_CTX_DAG_RUN_ID='scheduled__2024-05-02T00:00:00+00:00'
[2024-05-04T10:34:15.186+0000] {taskinstance.py:430} INFO - ::endgroup::
[2024-05-04T10:34:15.194+0000] {sql.py:276} INFO - Executing: SHOW DATABASES;
[2024-05-04T10:34:15.198+0000] {base.py:84} INFO - Using connection ID 'mysql_local' for task execution.
[2024-05-04T10:34:15.202+0000] {base.py:84} INFO - Using connection ID 'mysql_local' for task execution.
[2024-05-04T10:34:15.207+0000] {sql.py:457} INFO - Running statement: SHOW DATABASES;, parameters: None
[2024-05-04T10:34:15.209+0000] {sql.py:466} INFO - Rows affected: 7
[2024-05-04T10:34:15.212+0000] {logging_mixin.py:188} WARNING - /home/***/.local/lib/python3.12/site-packages/***/providers/common/sql/hooks/sql.py:407 AirflowProviderDeprecationWarning: Call to deprecated method _make_common_data_structure. (The `_make_serializable` method is deprecated and support will be removed in a future version of the common.sql provider. Please update the DbApiHook's provider to a version based on common.sql >= 1.9.1.)
[2024-05-04T10:34:15.213+0000] {taskinstance.py:441} INFO - ::group::Post task execution logs
[2024-05-04T10:34:15.222+0000] {taskinstance.py:1205} INFO - Marking task as SUCCESS. dag_id=dag_mysql, task_id=task1, execution_date=20240502T000000, start_date=20240504T103415, end_date=20240504T103415
[2024-05-04T10:34:15.269+0000] {local_task_job_runner.py:240} INFO - Task exited with return code 0
[2024-05-04T10:34:15.277+0000] {taskinstance.py:3482} INFO - 0 downstream tasks scheduled from follow-on schedule check
[2024-05-04T10:34:15.277+0000] {local_task_job_runner.py:222} INFO - ::endgroup::
[2024-05-04T10:40:40.253+0000] {local_task_job_runner.py:120} INFO - ::group::Pre task execution logs
[2024-05-04T10:40:40.278+0000] {taskinstance.py:2073} INFO - Dependencies all met for dep_context=non-requeueable deps ti=<TaskInstance: dag_mysql.task1 scheduled__2024-05-02T00:00:00+00:00 [queued]>
[2024-05-04T10:40:40.286+0000] {taskinstance.py:2073} INFO - Dependencies all met for dep_context=requeueable deps ti=<TaskInstance: dag_mysql.task1 scheduled__2024-05-02T00:00:00+00:00 [queued]>
[2024-05-04T10:40:40.287+0000] {taskinstance.py:2303} INFO - Starting attempt 1 of 6
[2024-05-04T10:40:40.302+0000] {taskinstance.py:2327} INFO - Executing <Task(MySqlOperator): task1> on 2024-05-02 00:00:00+00:00
[2024-05-04T10:40:40.310+0000] {logging_mixin.py:188} WARNING - /home/***/.local/lib/python3.12/site-packages/***/task/task_runner/standard_task_runner.py:61 DeprecationWarning: This process (pid=616) is multi-threaded, use of fork() may lead to deadlocks in the child.
[2024-05-04T10:40:40.312+0000] {standard_task_runner.py:63} INFO - Started process 622 to run task
[2024-05-04T10:40:40.311+0000] {standard_task_runner.py:90} INFO - Running: ['***', 'tasks', 'run', 'dag_mysql', 'task1', 'scheduled__2024-05-02T00:00:00+00:00', '--job-id', '39', '--raw', '--subdir', 'DAGS_FOLDER/dag_mysql.py', '--cfg-path', '/tmp/tmpsbtfk5pm']
[2024-05-04T10:40:40.315+0000] {standard_task_runner.py:91} INFO - Job 39: Subtask task1
[2024-05-04T10:40:40.363+0000] {task_command.py:426} INFO - Running <TaskInstance: dag_mysql.task1 scheduled__2024-05-02T00:00:00+00:00 [running]> on host f85b7a0b58b5
[2024-05-04T10:40:40.427+0000] {taskinstance.py:2644} INFO - Exporting env vars: AIRFLOW_CTX_DAG_OWNER='bses' AIRFLOW_CTX_DAG_ID='dag_mysql' AIRFLOW_CTX_TASK_ID='task1' AIRFLOW_CTX_EXECUTION_DATE='2024-05-02T00:00:00+00:00' AIRFLOW_CTX_TRY_NUMBER='1' AIRFLOW_CTX_DAG_RUN_ID='scheduled__2024-05-02T00:00:00+00:00'
[2024-05-04T10:40:40.428+0000] {taskinstance.py:430} INFO - ::endgroup::
[2024-05-04T10:40:40.437+0000] {sql.py:276} INFO - Executing: create table hello (name text, age int);
[2024-05-04T10:40:40.442+0000] {base.py:84} INFO - Using connection ID 'mysql_local' for task execution.
[2024-05-04T10:40:40.448+0000] {base.py:84} INFO - Using connection ID 'mysql_local' for task execution.
[2024-05-04T10:40:40.458+0000] {taskinstance.py:441} INFO - ::group::Post task execution logs
[2024-05-04T10:40:40.459+0000] {taskinstance.py:2890} ERROR - Task failed with exception
Traceback (most recent call last):
  File "/home/airflow/.local/lib/python3.12/site-packages/airflow/models/taskinstance.py", line 465, in _execute_task
    result = _execute_callable(context=context, **execute_callable_kwargs)
             ^^^^^^^^^^^^^^^^^^^^^^^^^^^^^^^^^^^^^^^^^^^^^^^^^^^^^^^^^^^^^
  File "/home/airflow/.local/lib/python3.12/site-packages/airflow/models/taskinstance.py", line 432, in _execute_callable
    return execute_callable(context=context, **execute_callable_kwargs)
           ^^^^^^^^^^^^^^^^^^^^^^^^^^^^^^^^^^^^^^^^^^^^^^^^^^^^^^^^^^^^
  File "/home/airflow/.local/lib/python3.12/site-packages/airflow/models/baseoperator.py", line 400, in wrapper
    return func(self, *args, **kwargs)
           ^^^^^^^^^^^^^^^^^^^^^^^^^^^
  File "/home/airflow/.local/lib/python3.12/site-packages/airflow/providers/common/sql/operators/sql.py", line 282, in execute
    output = hook.run(
             ^^^^^^^^^
  File "/home/airflow/.local/lib/python3.12/site-packages/airflow/providers/common/sql/hooks/sql.py", line 397, in run
    with closing(self.get_conn()) as conn:
                 ^^^^^^^^^^^^^^^
  File "/home/airflow/.local/lib/python3.12/site-packages/airflow/providers/mysql/hooks/mysql.py", line 195, in get_conn
    return MySQLdb.connect(**conn_config)
           ^^^^^^^^^^^^^^^^^^^^^^^^^^^^^^
  File "/home/airflow/.local/lib/python3.12/site-packages/MySQLdb/__init__.py", line 121, in Connect
    return Connection(*args, **kwargs)
           ^^^^^^^^^^^^^^^^^^^^^^^^^^^
  File "/home/airflow/.local/lib/python3.12/site-packages/MySQLdb/connections.py", line 195, in __init__
    super().__init__(*args, **kwargs2)
MySQLdb.OperationalError: (1524, "Plugin 'mysql_native_password' is not loaded")
[2024-05-04T10:40:40.465+0000] {taskinstance.py:1205} INFO - Marking task as UP_FOR_RETRY. dag_id=dag_mysql, task_id=task1, execution_date=20240502T000000, start_date=20240504T104040, end_date=20240504T104040
[2024-05-04T10:40:40.474+0000] {standard_task_runner.py:110} ERROR - Failed to execute job 39 for task task1 ((1524, "Plugin 'mysql_native_password' is not loaded"); 622)
[2024-05-04T10:40:40.496+0000] {local_task_job_runner.py:240} INFO - Task exited with return code 1
[2024-05-04T10:40:40.507+0000] {taskinstance.py:3482} INFO - 0 downstream tasks scheduled from follow-on schedule check
[2024-05-04T10:40:40.508+0000] {local_task_job_runner.py:222} INFO - ::endgroup::
[2024-05-04T10:42:21.540+0000] {local_task_job_runner.py:120} INFO - ::group::Pre task execution logs
[2024-05-04T10:42:21.556+0000] {taskinstance.py:2073} INFO - Dependencies all met for dep_context=non-requeueable deps ti=<TaskInstance: dag_mysql.task1 scheduled__2024-05-02T00:00:00+00:00 [queued]>
[2024-05-04T10:42:21.561+0000] {taskinstance.py:2073} INFO - Dependencies all met for dep_context=requeueable deps ti=<TaskInstance: dag_mysql.task1 scheduled__2024-05-02T00:00:00+00:00 [queued]>
[2024-05-04T10:42:21.562+0000] {taskinstance.py:2303} INFO - Starting attempt 1 of 6
[2024-05-04T10:42:21.571+0000] {taskinstance.py:2327} INFO - Executing <Task(MySqlOperator): task1> on 2024-05-02 00:00:00+00:00
[2024-05-04T10:42:21.579+0000] {standard_task_runner.py:90} INFO - Running: ['***', 'tasks', 'run', 'dag_mysql', 'task1', 'scheduled__2024-05-02T00:00:00+00:00', '--job-id', '45', '--raw', '--subdir', 'DAGS_FOLDER/dag_mysql.py', '--cfg-path', '/tmp/tmpdc9eylor']
[2024-05-04T10:42:21.580+0000] {logging_mixin.py:188} WARNING - /home/***/.local/lib/python3.12/site-packages/***/task/task_runner/standard_task_runner.py:61 DeprecationWarning: This process (pid=728) is multi-threaded, use of fork() may lead to deadlocks in the child.
[2024-05-04T10:42:21.584+0000] {standard_task_runner.py:91} INFO - Job 45: Subtask task1
[2024-05-04T10:42:21.584+0000] {standard_task_runner.py:63} INFO - Started process 735 to run task
[2024-05-04T10:42:21.613+0000] {task_command.py:426} INFO - Running <TaskInstance: dag_mysql.task1 scheduled__2024-05-02T00:00:00+00:00 [running]> on host f85b7a0b58b5
[2024-05-04T10:42:21.661+0000] {taskinstance.py:2644} INFO - Exporting env vars: AIRFLOW_CTX_DAG_OWNER='bses' AIRFLOW_CTX_DAG_ID='dag_mysql' AIRFLOW_CTX_TASK_ID='task1' AIRFLOW_CTX_EXECUTION_DATE='2024-05-02T00:00:00+00:00' AIRFLOW_CTX_TRY_NUMBER='1' AIRFLOW_CTX_DAG_RUN_ID='scheduled__2024-05-02T00:00:00+00:00'
[2024-05-04T10:42:21.663+0000] {taskinstance.py:430} INFO - ::endgroup::
[2024-05-04T10:42:21.673+0000] {sql.py:276} INFO - Executing: create table hello (name text, age int);
[2024-05-04T10:42:21.679+0000] {base.py:84} INFO - Using connection ID 'mysql_local' for task execution.
[2024-05-04T10:42:21.684+0000] {base.py:84} INFO - Using connection ID 'mysql_local' for task execution.
[2024-05-04T10:42:21.702+0000] {sql.py:457} INFO - Running statement: create table hello (name text, age int);, parameters: None
[2024-05-04T10:42:21.704+0000] {taskinstance.py:441} INFO - ::group::Post task execution logs
[2024-05-04T10:42:21.706+0000] {taskinstance.py:2890} ERROR - Task failed with exception
Traceback (most recent call last):
  File "/home/airflow/.local/lib/python3.12/site-packages/airflow/models/taskinstance.py", line 465, in _execute_task
    result = _execute_callable(context=context, **execute_callable_kwargs)
             ^^^^^^^^^^^^^^^^^^^^^^^^^^^^^^^^^^^^^^^^^^^^^^^^^^^^^^^^^^^^^
  File "/home/airflow/.local/lib/python3.12/site-packages/airflow/models/taskinstance.py", line 432, in _execute_callable
    return execute_callable(context=context, **execute_callable_kwargs)
           ^^^^^^^^^^^^^^^^^^^^^^^^^^^^^^^^^^^^^^^^^^^^^^^^^^^^^^^^^^^^
  File "/home/airflow/.local/lib/python3.12/site-packages/airflow/models/baseoperator.py", line 400, in wrapper
    return func(self, *args, **kwargs)
           ^^^^^^^^^^^^^^^^^^^^^^^^^^^
  File "/home/airflow/.local/lib/python3.12/site-packages/airflow/providers/common/sql/operators/sql.py", line 282, in execute
    output = hook.run(
             ^^^^^^^^^
  File "/home/airflow/.local/lib/python3.12/site-packages/airflow/providers/common/sql/hooks/sql.py", line 404, in run
    self._run_command(cur, sql_statement, parameters)
  File "/home/airflow/.local/lib/python3.12/site-packages/airflow/providers/common/sql/hooks/sql.py", line 462, in _run_command
    cur.execute(sql_statement)
  File "/home/airflow/.local/lib/python3.12/site-packages/MySQLdb/cursors.py", line 179, in execute
    res = self._query(mogrified_query)
          ^^^^^^^^^^^^^^^^^^^^^^^^^^^^
  File "/home/airflow/.local/lib/python3.12/site-packages/MySQLdb/cursors.py", line 330, in _query
    db.query(q)
  File "/home/airflow/.local/lib/python3.12/site-packages/MySQLdb/connections.py", line 261, in query
    _mysql.connection.query(self, query)
MySQLdb.OperationalError: (1050, "Table 'hello' already exists")
[2024-05-04T10:42:21.716+0000] {taskinstance.py:1205} INFO - Marking task as UP_FOR_RETRY. dag_id=dag_mysql, task_id=task1, execution_date=20240502T000000, start_date=20240504T104221, end_date=20240504T104221
[2024-05-04T10:42:21.723+0000] {standard_task_runner.py:110} ERROR - Failed to execute job 45 for task task1 ((1050, "Table 'hello' already exists"); 735)
[2024-05-04T10:42:21.765+0000] {local_task_job_runner.py:240} INFO - Task exited with return code 1
[2024-05-04T10:42:21.785+0000] {taskinstance.py:3482} INFO - 0 downstream tasks scheduled from follow-on schedule check
[2024-05-04T10:42:21.789+0000] {local_task_job_runner.py:222} INFO - ::endgroup::
