[2024-05-16T11:22:34.185+0000] {local_task_job_runner.py:120} INFO - ::group::Pre task execution logs
[2024-05-16T11:22:34.200+0000] {taskinstance.py:2073} INFO - Dependencies all met for dep_context=non-requeueable deps ti=<TaskInstance: dag_tables.import_table5 scheduled__2024-05-04T00:00:00+00:00 [queued]>
[2024-05-16T11:22:34.205+0000] {taskinstance.py:2073} INFO - Dependencies all met for dep_context=requeueable deps ti=<TaskInstance: dag_tables.import_table5 scheduled__2024-05-04T00:00:00+00:00 [queued]>
[2024-05-16T11:22:34.205+0000] {taskinstance.py:2303} INFO - Starting attempt 1 of 6
[2024-05-16T11:22:34.212+0000] {taskinstance.py:2327} INFO - Executing <Task(BashOperator): import_table5> on 2024-05-04 00:00:00+00:00
[2024-05-16T11:22:34.216+0000] {logging_mixin.py:188} WARNING - /home/***/.local/lib/python3.12/site-packages/***/task/task_runner/standard_task_runner.py:61 DeprecationWarning: This process (pid=613) is multi-threaded, use of fork() may lead to deadlocks in the child.
[2024-05-16T11:22:34.217+0000] {standard_task_runner.py:63} INFO - Started process 615 to run task
[2024-05-16T11:22:34.216+0000] {standard_task_runner.py:90} INFO - Running: ['***', 'tasks', 'run', 'dag_tables', 'import_table5', 'scheduled__2024-05-04T00:00:00+00:00', '--job-id', '473', '--raw', '--subdir', 'DAGS_FOLDER/dag_mysql.py', '--cfg-path', '/tmp/tmp7sgful3v']
[2024-05-16T11:22:34.218+0000] {standard_task_runner.py:91} INFO - Job 473: Subtask import_table5
[2024-05-16T11:22:34.245+0000] {task_command.py:426} INFO - Running <TaskInstance: dag_tables.import_table5 scheduled__2024-05-04T00:00:00+00:00 [running]> on host 7084a6d88d3b
[2024-05-16T11:22:34.287+0000] {taskinstance.py:2644} INFO - Exporting env vars: AIRFLOW_CTX_DAG_OWNER='bses' AIRFLOW_CTX_DAG_ID='dag_tables' AIRFLOW_CTX_TASK_ID='import_table5' AIRFLOW_CTX_EXECUTION_DATE='2024-05-04T00:00:00+00:00' AIRFLOW_CTX_TRY_NUMBER='1' AIRFLOW_CTX_DAG_RUN_ID='scheduled__2024-05-04T00:00:00+00:00'
[2024-05-16T11:22:34.288+0000] {taskinstance.py:430} INFO - ::endgroup::
[2024-05-16T11:22:34.294+0000] {subprocess.py:63} INFO - Tmp dir root location: /tmp
[2024-05-16T11:22:34.295+0000] {subprocess.py:75} INFO - Running command: ['/usr/bin/bash', '-c', '\n                mysql -h host.docker.internal -u root --password=12345678 test < /opt/***/dags/rw_transaction_data.sql\n                ']
[2024-05-16T11:22:34.305+0000] {subprocess.py:86} INFO - Output:
[2024-05-16T11:22:34.596+0000] {subprocess.py:93} INFO - ERROR 1100 (HY000) at line 59: Table 'rw_transaction_500_demo' was not locked with LOCK TABLES
[2024-05-16T11:22:34.598+0000] {subprocess.py:97} INFO - Command exited with return code 1
[2024-05-16T11:22:34.598+0000] {taskinstance.py:441} INFO - ::group::Post task execution logs
[2024-05-16T11:22:34.605+0000] {taskinstance.py:2890} ERROR - Task failed with exception
Traceback (most recent call last):
  File "/home/airflow/.local/lib/python3.12/site-packages/airflow/models/taskinstance.py", line 465, in _execute_task
    result = _execute_callable(context=context, **execute_callable_kwargs)
             ^^^^^^^^^^^^^^^^^^^^^^^^^^^^^^^^^^^^^^^^^^^^^^^^^^^^^^^^^^^^^
  File "/home/airflow/.local/lib/python3.12/site-packages/airflow/models/taskinstance.py", line 432, in _execute_callable
    return execute_callable(context=context, **execute_callable_kwargs)
           ^^^^^^^^^^^^^^^^^^^^^^^^^^^^^^^^^^^^^^^^^^^^^^^^^^^^^^^^^^^^
  File "/home/airflow/.local/lib/python3.12/site-packages/airflow/models/baseoperator.py", line 400, in wrapper
    return func(self, *args, **kwargs)
           ^^^^^^^^^^^^^^^^^^^^^^^^^^^
  File "/home/airflow/.local/lib/python3.12/site-packages/airflow/operators/bash.py", line 243, in execute
    raise AirflowException(
airflow.exceptions.AirflowException: Bash command failed. The command returned a non-zero exit code 1.
[2024-05-16T11:22:34.608+0000] {taskinstance.py:1205} INFO - Marking task as UP_FOR_RETRY. dag_id=dag_tables, task_id=import_table5, execution_date=20240504T000000, start_date=20240516T112234, end_date=20240516T112234
[2024-05-16T11:22:34.614+0000] {standard_task_runner.py:110} ERROR - Failed to execute job 473 for task import_table5 (Bash command failed. The command returned a non-zero exit code 1.; 615)
[2024-05-16T11:22:34.642+0000] {local_task_job_runner.py:240} INFO - Task exited with return code 1
[2024-05-16T11:22:34.654+0000] {taskinstance.py:3482} INFO - 0 downstream tasks scheduled from follow-on schedule check
[2024-05-16T11:22:34.655+0000] {local_task_job_runner.py:222} INFO - ::endgroup::
