[2024-05-16T03:57:37.975+0000] {local_task_job_runner.py:120} INFO - ::group::Pre task execution logs
[2024-05-16T03:57:38.038+0000] {taskinstance.py:2073} INFO - Dependencies all met for dep_context=non-requeueable deps ti=<TaskInstance: dag_hdfs.save_csv scheduled__2024-05-06T00:00:00+00:00 [queued]>
[2024-05-16T03:57:38.050+0000] {taskinstance.py:2073} INFO - Dependencies all met for dep_context=requeueable deps ti=<TaskInstance: dag_hdfs.save_csv scheduled__2024-05-06T00:00:00+00:00 [queued]>
[2024-05-16T03:57:38.052+0000] {taskinstance.py:2303} INFO - Starting attempt 3 of 6
[2024-05-16T03:57:38.091+0000] {taskinstance.py:2327} INFO - Executing <Task(PythonOperator): save_csv> on 2024-05-06 00:00:00+00:00
[2024-05-16T03:57:38.122+0000] {logging_mixin.py:188} WARNING - /home/***/.local/lib/python3.12/site-packages/***/task/task_runner/standard_task_runner.py:61 DeprecationWarning: This process (pid=872) is multi-threaded, use of fork() may lead to deadlocks in the child.
[2024-05-16T03:57:38.130+0000] {standard_task_runner.py:63} INFO - Started process 888 to run task
[2024-05-16T03:57:38.125+0000] {standard_task_runner.py:90} INFO - Running: ['***', 'tasks', 'run', 'dag_hdfs', 'save_csv', 'scheduled__2024-05-06T00:00:00+00:00', '--job-id', '322', '--raw', '--subdir', 'DAGS_FOLDER/dag_hdfs.py', '--cfg-path', '/tmp/tmps1_gy3ur']
[2024-05-16T03:57:38.138+0000] {standard_task_runner.py:91} INFO - Job 322: Subtask save_csv
[2024-05-16T03:57:38.258+0000] {task_command.py:426} INFO - Running <TaskInstance: dag_hdfs.save_csv scheduled__2024-05-06T00:00:00+00:00 [running]> on host a7dbb8bad76e
[2024-05-16T03:57:38.481+0000] {taskinstance.py:2644} INFO - Exporting env vars: AIRFLOW_CTX_DAG_OWNER='bses' AIRFLOW_CTX_DAG_ID='dag_hdfs' AIRFLOW_CTX_TASK_ID='save_csv' AIRFLOW_CTX_EXECUTION_DATE='2024-05-06T00:00:00+00:00' AIRFLOW_CTX_TRY_NUMBER='3' AIRFLOW_CTX_DAG_RUN_ID='scheduled__2024-05-06T00:00:00+00:00'
[2024-05-16T03:57:38.485+0000] {taskinstance.py:430} INFO - ::endgroup::
[2024-05-16T03:57:38.510+0000] {client.py:192} INFO - Instantiated <InsecureClient(url='http://localhost:9870')>.
[2024-05-16T03:57:38.518+0000] {client.py:551} INFO - Uploading '/Users/bses/F1_Intern/Hadoop_Mani/museum.csv' to '/bses'.
[2024-05-16T03:57:38.524+0000] {client.py:1116} INFO - Listing '/bses'.
[2024-05-16T03:57:38.532+0000] {taskinstance.py:441} INFO - ::group::Post task execution logs
[2024-05-16T03:57:38.532+0000] {taskinstance.py:2890} ERROR - Task failed with exception
Traceback (most recent call last):
  File "/home/airflow/.local/lib/python3.12/site-packages/urllib3/connection.py", line 174, in _new_conn
    conn = connection.create_connection(
           ^^^^^^^^^^^^^^^^^^^^^^^^^^^^^
  File "/home/airflow/.local/lib/python3.12/site-packages/urllib3/util/connection.py", line 95, in create_connection
    raise err
  File "/home/airflow/.local/lib/python3.12/site-packages/urllib3/util/connection.py", line 85, in create_connection
    sock.connect(sa)
ConnectionRefusedError: [Errno 111] Connection refused

During handling of the above exception, another exception occurred:

Traceback (most recent call last):
  File "/home/airflow/.local/lib/python3.12/site-packages/urllib3/connectionpool.py", line 715, in urlopen
    httplib_response = self._make_request(
                       ^^^^^^^^^^^^^^^^^^^
  File "/home/airflow/.local/lib/python3.12/site-packages/urllib3/connectionpool.py", line 416, in _make_request
    conn.request(method, url, **httplib_request_kw)
  File "/home/airflow/.local/lib/python3.12/site-packages/urllib3/connection.py", line 244, in request
    super(HTTPConnection, self).request(method, url, body=body, headers=headers)
  File "/usr/local/lib/python3.12/http/client.py", line 1331, in request
    self._send_request(method, url, body, headers, encode_chunked)
  File "/usr/local/lib/python3.12/http/client.py", line 1377, in _send_request
    self.endheaders(body, encode_chunked=encode_chunked)
  File "/usr/local/lib/python3.12/http/client.py", line 1326, in endheaders
    self._send_output(message_body, encode_chunked=encode_chunked)
  File "/usr/local/lib/python3.12/http/client.py", line 1085, in _send_output
    self.send(msg)
  File "/usr/local/lib/python3.12/http/client.py", line 1029, in send
    self.connect()
  File "/home/airflow/.local/lib/python3.12/site-packages/urllib3/connection.py", line 205, in connect
    conn = self._new_conn()
           ^^^^^^^^^^^^^^^^
  File "/home/airflow/.local/lib/python3.12/site-packages/urllib3/connection.py", line 186, in _new_conn
    raise NewConnectionError(
urllib3.exceptions.NewConnectionError: <urllib3.connection.HTTPConnection object at 0xffff9a545190>: Failed to establish a new connection: [Errno 111] Connection refused

During handling of the above exception, another exception occurred:

Traceback (most recent call last):
  File "/home/airflow/.local/lib/python3.12/site-packages/requests/adapters.py", line 486, in send
    resp = conn.urlopen(
           ^^^^^^^^^^^^^
  File "/home/airflow/.local/lib/python3.12/site-packages/urllib3/connectionpool.py", line 799, in urlopen
    retries = retries.increment(
              ^^^^^^^^^^^^^^^^^^
  File "/home/airflow/.local/lib/python3.12/site-packages/urllib3/util/retry.py", line 592, in increment
    raise MaxRetryError(_pool, url, error or ResponseError(cause))
urllib3.exceptions.MaxRetryError: HTTPConnectionPool(host='localhost', port=9870): Max retries exceeded with url: /webhdfs/v1/bses?user.name=***&op=LISTSTATUS (Caused by NewConnectionError('<urllib3.connection.HTTPConnection object at 0xffff9a545190>: Failed to establish a new connection: [Errno 111] Connection refused'))

During handling of the above exception, another exception occurred:

Traceback (most recent call last):
  File "/home/airflow/.local/lib/python3.12/site-packages/airflow/models/taskinstance.py", line 465, in _execute_task
    result = _execute_callable(context=context, **execute_callable_kwargs)
             ^^^^^^^^^^^^^^^^^^^^^^^^^^^^^^^^^^^^^^^^^^^^^^^^^^^^^^^^^^^^^
  File "/home/airflow/.local/lib/python3.12/site-packages/airflow/models/taskinstance.py", line 432, in _execute_callable
    return execute_callable(context=context, **execute_callable_kwargs)
           ^^^^^^^^^^^^^^^^^^^^^^^^^^^^^^^^^^^^^^^^^^^^^^^^^^^^^^^^^^^^
  File "/home/airflow/.local/lib/python3.12/site-packages/airflow/models/baseoperator.py", line 400, in wrapper
    return func(self, *args, **kwargs)
           ^^^^^^^^^^^^^^^^^^^^^^^^^^^
  File "/home/airflow/.local/lib/python3.12/site-packages/airflow/operators/python.py", line 235, in execute
    return_value = self.execute_callable()
                   ^^^^^^^^^^^^^^^^^^^^^^^
  File "/home/airflow/.local/lib/python3.12/site-packages/airflow/operators/python.py", line 252, in execute_callable
    return self.python_callable(*self.op_args, **self.op_kwargs)
           ^^^^^^^^^^^^^^^^^^^^^^^^^^^^^^^^^^^^^^^^^^^^^^^^^^^^^
  File "/opt/airflow/dags/dag_hdfs.py", line 12, in save
    client.upload(hdfs_upload_path, local_csv_file_path)
  File "/home/airflow/.local/lib/python3.12/site-packages/hdfs/client.py", line 580, in upload
    statuses = [status for _, status in self.list(hdfs_path, status=True)]
                                        ^^^^^^^^^^^^^^^^^^^^^^^^^^^^^^^^^
  File "/home/airflow/.local/lib/python3.12/site-packages/hdfs/client.py", line 1118, in list
    statuses = self._list_status(hdfs_path).json()['FileStatuses']['FileStatus']
               ^^^^^^^^^^^^^^^^^^^^^^^^^^^^
  File "/home/airflow/.local/lib/python3.12/site-packages/hdfs/client.py", line 125, in api_handler
    raise err
  File "/home/airflow/.local/lib/python3.12/site-packages/hdfs/client.py", line 102, in api_handler
    res = client._request(
          ^^^^^^^^^^^^^^^^
  File "/home/airflow/.local/lib/python3.12/site-packages/hdfs/client.py", line 209, in _request
    return self._session.request(
           ^^^^^^^^^^^^^^^^^^^^^^
  File "/home/airflow/.local/lib/python3.12/site-packages/requests/sessions.py", line 589, in request
    resp = self.send(prep, **send_kwargs)
           ^^^^^^^^^^^^^^^^^^^^^^^^^^^^^^
  File "/home/airflow/.local/lib/python3.12/site-packages/requests/sessions.py", line 703, in send
    r = adapter.send(request, **kwargs)
        ^^^^^^^^^^^^^^^^^^^^^^^^^^^^^^^
  File "/home/airflow/.local/lib/python3.12/site-packages/requests/adapters.py", line 519, in send
    raise ConnectionError(e, request=request)
requests.exceptions.ConnectionError: HTTPConnectionPool(host='localhost', port=9870): Max retries exceeded with url: /webhdfs/v1/bses?user.name=***&op=LISTSTATUS (Caused by NewConnectionError('<urllib3.connection.HTTPConnection object at 0xffff9a545190>: Failed to establish a new connection: [Errno 111] Connection refused'))
[2024-05-16T03:57:38.547+0000] {taskinstance.py:1205} INFO - Marking task as UP_FOR_RETRY. dag_id=dag_hdfs, task_id=save_csv, execution_date=20240506T000000, start_date=20240516T035738, end_date=20240516T035738
[2024-05-16T03:57:38.555+0000] {standard_task_runner.py:110} ERROR - Failed to execute job 322 for task save_csv (HTTPConnectionPool(host='localhost', port=9870): Max retries exceeded with url: /webhdfs/v1/bses?user.name=***&op=LISTSTATUS (Caused by NewConnectionError('<urllib3.connection.HTTPConnection object at 0xffff9a545190>: Failed to establish a new connection: [Errno 111] Connection refused')); 888)
[2024-05-16T03:57:38.579+0000] {local_task_job_runner.py:240} INFO - Task exited with return code 1
[2024-05-16T03:57:38.597+0000] {taskinstance.py:3482} INFO - 0 downstream tasks scheduled from follow-on schedule check
[2024-05-16T03:57:38.606+0000] {local_task_job_runner.py:222} INFO - ::endgroup::
